Workbook

Sheet Dashboard

Sheet Summary
A1: =TODAY() -> 46218
M2: Monitoring Surat 2026
A3: Keterangan | M3: Keterangan | N3: Compliance | O3: Corcom | P3: Finance | Q3: HC | R3: HSE | V3: Maintenance | W3: Permit | X3: Planning | Y3: PMO | Z3: Produksi | AA3: SCM | AB3: QMS | AC3: WQA
A4: Level 1 | B4: Perlu dibalas dengan tenggat waktu (max 7 hari) | M4: Incoming Open | N4: =COUNTIFS('Incoming 2026'!L:L,$B$19,'Incoming 2026'!N:N,N3) -> 3 | O4: =COUNTIFS('Incoming 2026'!L:L,$B$19,'Incoming 2026'!N:N,"$O$3") -> 0 | P4: =COUNTIFS('Incoming 2026'!L:L,$B$19,'Incoming 2026'!N:N,"HC") -> 0 | Q4: =COUNTIFS('Incoming 2026'!L:L,$B$19,'Incoming 2026'!N:N,"HC") -> 0 | R4: =COUNTIFS('Incoming 2026'!L:L,$B$19,'Incoming 2026'!N:N,"HSE") -> 29 | V4: =COUNTIFS('Incoming 2026'!L:L,$B$19,'Incoming 2026'!N:N,"maintenance") -> 0 | W4: =COUNTIFS('Incoming 2026'!L:L,$B$19,'Incoming 2026'!N:N,"permit") -> 2 | X4: =COUNTIFS('Incoming 2026'!L:L,$B$19,'Incoming 2026'!N:N,"Planning") -> 16 | Y4: =COUNTIFS('Incoming 2026'!L:L,$B$19,'Incoming 2026'!N:N,"PMO") -> 1 | Z4: =COUNTIFS('Incoming 2026'!L:L,$B$19,'Incoming 2026'!N:N,"Produksi") -> 2 | AA4: =COUNTIFS('Incoming 2024'!L:L,$B$19,'Incoming 2024'!N:N,"SCM") -> 0 | AB4: =COUNTIFS('Incoming 2024'!L:L,$B$19,'Incoming 2024'!N:N,"QMS") -> 0 | AC4: =COUNTIFS('Incoming 2024'!L:L,$B$19,'Incoming 2024'!N:N,"WQA") -> 0
A5: Level 2 | B5: Perlu dibalas dengan tenggat waktu (Max 14 hari) | M5: Incoming Closed | N5: =COUNTIFS('Incoming 2026'!L:L,Summary!$B$20,'Incoming 2026'!N:N,Summary!N3) -> 11 | O5: =COUNTIFS('Incoming 2026'!L:L,Summary!$B$20,'Incoming 2026'!N:N,Summary!O3) -> 0 | P5: =COUNTIFS('Incoming 2026'!L:L,Summary!$B$20,'Incoming 2026'!N:N,Summary!P3) -> 4 | Q5: =COUNTIFS('Incoming 2026'!L:L,Summary!$B$20,'Incoming 2026'!N:N,Summary!Q3) -> 0 | R5: =COUNTIFS('Incoming 2026'!L:L,Summary!$B$20,'Incoming 2026'!N:N,Summary!R3) -> 23 | V5: =COUNTIFS('Incoming 2026'!L:L,Summary!$B$20,'Incoming 2026'!N:N,Summary!V3) -> 0 | W5: =COUNTIFS('Incoming 2026'!L:L,Summary!$B$20,'Incoming 2026'!N:N,Summary!W3) -> 2 | X5: =COUNTIFS('Incoming 2026'!L:L,Summary!$B$20,'Incoming 2026'!N:N,Summary!X3) -> 2 | Y5: =COUNTIFS('Incoming 2026'!L:L,Summary!$B$20,'Incoming 2026'!N:N,Summary!Y3) -> 0 | Z5: =COUNTIFS('Incoming 2026'!L:L,Summary!$B$20,'Incoming 2026'!N:N,Summary!Z3) -> 7 | AA5: =COUNTIFS('Incoming 2024'!L:L,Summary!$B$20,'Incoming 2024'!N:N,Summary!AA3) -> 0 | AB5: =COUNTIFS('Incoming 2024'!L:L,Summary!$B$20,'Incoming 2024'!N:N,Summary!AB3) -> 1 | AC5: =COUNTIFS('Incoming 2024'!L:L,Summary!$B$20,'Incoming 2024'!N:N,Summary!AC3) -> 2
A6: Level 3 | B6: Perlu dibalas dengan tenggat waktu (Max 30 hari) | M6: Outgoing Open | N6: =COUNTIFS('Outgoing 2026'!K:K,$B$19,'Outgoing 2026'!L:L,"compliance") -> 11 | O6: =COUNTIFS('Outgoing 2026'!K:K,$B$19,'Outgoing 2026'!L:L,"corcom") -> 0 | P6: =COUNTIFS('Outgoing 2026'!K:K,$B$19,'Outgoing 2026'!L:L,"Finance") -> 0 | Q6: =COUNTIFS('Outgoing 2026'!K:K,$B$19,'Outgoing 2026'!L:L,"HC") -> 0 | R6: =COUNTIFS('Outgoing 2026'!K:K,$B$19,'Outgoing 2026'!L:L,"HSE") -> 0 | V6: =COUNTIFS('Outgoing 2026'!K:K,$B$19,'Outgoing 2026'!L:L,"Maintenance") -> 0 | W6: =COUNTIFS('Outgoing 2026'!K:K,$B$19,'Outgoing 2026'!L:L,"Permit") -> 2 | X6: =COUNTIFS('Outgoing 2026'!K:K,$B$19,'Outgoing 2026'!L:L,"Planning") -> 0 | Y6: =COUNTIFS('Outgoing 2026'!K:K,$B$19,'Outgoing 2026'!L:L,$Y$3) -> 0 | Z6: =COUNTIFS('Outgoing 2026'!K:K,$B$19,'Outgoing 2026'!L:L,$Z$3) -> 2 | AA6: =COUNTIFS('Outgoing 2024'!K:K,$B$19,'Outgoing 2024'!L:L,$AA$3) -> 0 | AB6: =COUNTIFS('Outgoing 2024'!K:K,$B$19,'Outgoing 2024'!L:L,$AB$3) -> 0 | AC6: =COUNTIFS('Outgoing 2024'!K:K,$B$19,'Outgoing 2024'!L:L,$AC$3) -> 0
M7: Outgoing Closed | N7: =COUNTIFS('Outgoing 2026'!K:K,$B$20,'Outgoing 2026'!L:L,"compliance") -> 21 | O7: =COUNTIFS('Outgoing 2026'!K:K,$B$20,'Outgoing 2026'!L:L,"corcom") -> 0 | P7: =COUNTIFS('Outgoing 2026'!K:K,$B$20,'Outgoing 2026'!L:L,"Finance") -> 0 | Q7: =COUNTIFS('Outgoing 2026'!K:K,$B$20,'Outgoing 2026'!L:L,"HC") -> 0 | R7: =COUNTIFS('Outgoing 2026'!K:K,$B$20,'Outgoing 2026'!L:L,"HSE") -> 0 | V7: =COUNTIFS('Outgoing 2026'!K:K,$B$20,'Outgoing 2026'!L:L,"Maintenance") -> 0 | W7: =COUNTIFS('Outgoing 2026'!K:K,$B$20,'Outgoing 2026'!L:L,"Permit") -> 0 | X7: =COUNTIFS('Outgoing 2026'!K:K,$B$20,'Outgoing 2026'!L:L,"Planning") -> 0 | Y7: =COUNTIFS('Outgoing 2026'!K:K,$B$20,'Outgoing 2026'!L:L,$Y$3) -> 0 | Z7: =COUNTIFS('Outgoing 2026'!K:K,$B$20,'Outgoing 2026'!L:L,$Z$3) -> 0 | AA7: =COUNTIFS('Outgoing 2024'!K:K,$B$20,'Outgoing 2024'!L:L,$AA$3) -> 0 | AB7: =COUNTIFS('Outgoing 2024'!K:K,$B$20,'Outgoing 2024'!L:L,$AB$3) -> 0 | AC7: =COUNTIFS('Outgoing 2024'!K:K,$B$20,'Outgoing 2024'!L:L,$AC$3) -> 1
A8: 1) Total Surat | B8: 2023 | C8: Incoming | D8: =SUBTOTAL(3,'Incoming 2023'!D:D) -> 439
C9: Outgoing | D9: =SUBTOTAL(3,'Outgoing 2023'!B:B) -> 531
B10: 2024 | C10: Incoming | D10: =SUBTOTAL(3,'Incoming 2024'!B:B) -> 835
C11: Outgoing | D11: =SUBTOTAL(3,'Outgoing 2024'!A:A) -> 975
B12: 2025 | C12: Incoming | D12: =SUBTOTAL(3,'Incoming 2025'!B2:B2001) -> 502
C13: Outgoing | D13: =SUBTOTAL(3,'Outgoing 2025'!B2:B1898) -> 1158
B14: 2026 | C14: Incoming | D14: =SUBTOTAL(3,'Incoming 2026'!B2:B1990) -> 304
C15: Outgoing | D15: =SUBTOTAL(3,'Outgoing 2026'!B2:B961) -> 820
B18: Surat Masuk | C18: 2026 | D18: 2025 | E18: 2024 | F18: 2023 | I18: Surat Keluar | J18: 2026 | K18: 2025 | L18: 2024
B19: Open | C19: =COUNTIF('Incoming 2026'!L2:L1988,Summary!B19) -> 98 | D19: =COUNTIF('Incoming 2025'!L2:L2001,Summary!B19) -> 44 | E19: =COUNTIF('Incoming 2024'!L:L,"open") -> 37 | F19: =COUNTIF('Incoming 2023'!I:I,"open") -> 9 | I19: Open | J19: =COUNTIF('Outgoing 2026'!$K$2:$K$961,Summary!I19) -> 24 | K19: =COUNTIF('Outgoing 2025'!K2:K963,Summary!I19) -> 11 | L19: =COUNTIF('Outgoing 2024'!K:K,"Open") -> 2
B20: Closed | C20: =COUNTIF('Incoming 2026'!L2:L1988,Summary!B20) -> 70 | D20: =COUNTIF('Incoming 2025'!L3:L2001,Summary!B20) -> 111 | E20: =COUNTIF('Incoming 2024'!L:L,"closed") -> 244 | F20: =COUNTIF('Incoming 2023'!I:I,"closed") -> 252 | I20: Closed | J20: =COUNTIF('Outgoing 2026'!$K$2:$K$961,Summary!I20) -> 25 | K20: =COUNTIF('Outgoing 2025'!K3:K963,Summary!I20) -> 7 | L20: =COUNTIF('Outgoing 2024'!K:K,"Closed") -> 177
B21: Info | C21: =COUNTIF('Incoming 2026'!L2:L1989,Summary!B21) -> 136 | D21: =COUNTIF('Incoming 2025'!L4:L1001,Summary!B21) -> 338 | E21: =COUNTIF('Incoming 2024'!L:L,"info") -> 553 | F21: =COUNTIF('Incoming 2023'!I:I,"info") -> 177 | I21: Info | J21: =COUNTIF('Outgoing 2026'!$K$2:$K$961,Summary!I21) -> 643 | K21: =COUNTIF('Outgoing 2025'!K4:K963,Summary!I21) -> 639 | L21: =COUNTIF('Outgoing 2024'!K:K,"Info") -> 777
M34: Jumlah surat masuk berdasarkan Durasi Keterlambatan
N35: 7 | O35: 14 | P35: 21 | Q35: 30
M36: Level 1 | N36: =COUNTIF('Incoming 2026'!M2:M192,Summary!M36) -> 23 | O36: =COUNTIFS('Incoming 2026'!M:M,Summary!M36,'Incoming 2026'!S:S,Summary!O35) -> 2 | P36: =COUNTIFS('Incoming 2026'!M:M,Summary!M36,'Incoming 2026'!S:S,Summary!P35) -> 3 | Q36: =COUNTIFS('Incoming 2026'!M:M,Summary!N36,'Incoming 2026'!S:S,Summary!Q35) -> 0
M37: Level 2 | N37: =COUNTIF('Incoming 2026'!M3:M193,Summary!M37) -> 33 | O37: =COUNTIFS('Incoming 2026'!M:M,Summary!M37,'Incoming 2026'!S:S,Summary!O35) -> 0 | P37: =COUNTIFS('Incoming 2026'!M:M,Summary!M37,'Incoming 2026'!S:S,Summary!P35) -> 0 | Q37: =COUNTIFS('Incoming 2026'!M:M,Summary!M37,'Incoming 2026'!S:S,Summary!Q35) -> 0
M38: Level 3 | N38: =COUNTIF('Incoming 2026'!M4:M194,Summary!M38) -> 3 | O38: =COUNTIFS('Incoming 2026'!M:M,Summary!M38,'Incoming 2026'!S:S,Summary!O35) -> 0 | P38: =COUNTIFS('Incoming 2026'!M:M,Summary!M38,'Incoming 2026'!S:S,Summary!P35) -> 0 | Q38: =COUNTIFS('Incoming 2026'!M:M,Summary!M38,'Incoming 2026'!S:S,Summary!Q35) -> 4
A40: Kategori Surat
A41: TOK | B41: =COUNTIF('Incoming 2026'!#REF!,A41) -> #REF!
A42: DED/RAB | B42: =COUNTIF('Incoming 2026'!#REF!,A42) -> #REF!
A43: PKS | B43: =COUNTIF('Incoming 2026'!#REF!,A43) -> #REF!
A44: Dokumentasi | B44: =COUNTIF('Incoming 2026'!#REF!,A44) -> #REF!
A45: Denda | B45: =COUNTIF('Incoming 2026'!#REF!,A45) -> #REF!
A46: Perizinan | B46: =COUNTIF('Incoming 2026'!#REF!,A46) -> #REF!
A47: Sambungan Rumah/Sambungan Baru | B47: =COUNTIF('Incoming 2026'!#REF!,A47) -> #REF!
A48: Teguran | B48: =COUNTIF('Incoming 2026'!#REF!,A48) -> #REF!
A49: Komisioning/Pengoperasian | B49: =COUNTIF('Incoming 2026'!#REF!,A49) -> #REF!
A50: Spesifikasi Teknis/Metode Kerja | B50: =COUNTIF('Incoming 2026'!#REF!,A50) -> #REF!
A51: Inspeksi | B51: =COUNTIF('Incoming 2026'!#REF!,A51) -> #REF!
A53: Pengadaan | B53: =COUNTIF('Incoming 2026'!#REF!,A53) -> #REF!
... A56: Rencana Pekerjaan | B56: =COUNTIF('Incoming 2026'!#REF!,A56) -> #REF!
A59: Kategori Surat Masuk "Open"
A60: Shop Drawing | B60: =COUNTIFS('Incoming 2025'!L:L,Summary!$B$19,'Incoming 2025'!J:J,Summary!A60) -> 0
...

Sheet Reminder
A1: Reminder Surat Masuk
A2: No | B2: Nomor Surat | C2: Perihal | D2: Keterangan | E2: PIC | F2: Due Date | G2: Status
A3: 1 | B3: e-72456/PS.04.00 | C3: Permintaan Pemenuhan Realisasi Investasi Amandemen dan Pernyataan Kembali Perjanjian Greenfield Periode Tahun 2026 | D3: PAM JAYA mengingatkan ABJ untuk memenuhi kewajiban investasi sebagaimana PKS A&R Greenfield | E3: Compliance; PGO; Legal A. Levi; Lusian F; Bahtera | F3: 46224
A4: 2 | B4: e-76222/PP.01.02 | C4: Teguran Permintaan Pemenuhan Kewajiban Penyelesaian Paket Pekerjaan Ketiga atau Tanggal Operasi Komersial 5 April 2026 | D4: PAM JAYA menyampaikan progres TOK 5 April 2026, di mana dari 108 program terdapat 18 program batal, 30 selesai, dan 60 masih berjalan, serta meminta PT ABJ memastikan penyelesaian pekerjaan, kelengkapan dokumen, perizinan, dan pembaruan progres sesuai ketentuan. | E4: PMO/PGO-Suci/Lusian F | F4: 46224
A5: 3 | B5: e-76340/PS.04.06 | C5: Permintaan Program Kepastian Kualitas terkait Kualitas Pekerjaan pada Proyek Bundling | D5: ABJ diminta menyampaikan dan menjalankan program kepastian kualitas (SOP, ITP, checklist) untuk seluruh tahap proyek, serta memastikan pekerjaan sesuai standar dan mematuhi perjanjian dengan PAM JAYA. | E5: Compliance; PGO; QMS-A. Levi; Lusian F; Sri H | F5: 46224
A6: 4 | B6: e-76450/PP.00.02 | C6: Permintaan Penyampaian Konfirmasi Progress Infill Percepatan | D6: PT ABJ belum menyampaikan pemutakhiran Desain Akhir Proyek Greenfield. ABJ diminta unggah data ke BIM, pembaruan database dan status pekerjaan, serta kepatuhan terhadap perjanjian kerja sama. | E6: Planning-Aji S | F6: 46224
A7: 5 | B7: E-77961/PP.01.02 | C7: Surat Teguran atas Tidak Sesuainya Penerapan Aspek Keselamatan dan Kesehatan Kerja (K3) dan Ketidaksesuaian Pelaksanaan Pengurugan dan Perbaikan Bekas Galian yang Berdampak pada Kecelakaan Lalu Lintas dan Citra Buruk PAM JAYA pada Masyarakat | D7: PAM JAYA meminta ABJ untuk menindaklanjuti seluruh temuan dalam 1x24 jam; Melaksanakan pengawasan dan monitoring; Memastikan tidak adanya pelanggaran K3 | E7: HSE-Irsan/Suhendro | F7: 46224
A8: 6 | B8: e-78854/PP.01.02 | C8: Teguran Penerapan Aspek K3 pada proyek Buaran Hilir | D8: Teguran berulang atas atas pelanggaran K3 berulang pada proyek Buaran Hilir dan meminta perbaikan segera, pengawasan lebih ketat, penerapan K3 yang konsisten, serta kepatuhan penuh terhadap ketentuan perjanjian. | E8: HSE-Irsan/Suhendro | F8: 46224
A9: 7 | B9: e-78852/PS.04.06 | C9: Pemuktahiran Hak Akses PAM JAYA | D9: PAM JAYA meminta PT ABJ memberikan akses kepada karyawan dan perwakilan sah PAM JAYA untuk memasuki lokasi proyek sesuai ketentuan perjanjian. (152 user) | E9: Compliance-A. Levi | F9: 46224
A10: 8 | B10: 271/SCI-KPI/V/2026 | C10: Tanggapan atas Surat PT Air Bersih Jakarta No. ABJ/DIR/EKS/05.26/0511 Tentang Penyampaian Informasi Proyek SPAM Buaran 3 Hilir – PC 161 JDU | D10: ABJ diminta untuk membuat justifikasi teknis dan justifikasi finansial dalam perubahan metode pemasangan pipa crossing | E10: PMO Infill-Topan | F10: 46224
A11: 9 | B11: 1960/PS.04.05/EKST/V/2026 | C11: Permintaan Pemenuhan Perizinan Pekerjaan TOK 5 Oktober 2026 | D11: (i) ABJ wajib menyelesaikan seluruh perizinan proyek. (ii) PAM JAYA meminta percepatan izin untuk target TOK 5 Oktober 2026. (iii) ABJ wajib lapor progres perizinan rutin setiap Kamis pukul 15.00 WIB. (iv) Semua izin harus valid agar proyek tidak terlambat. | E11: Permit-Rudy | F11: 46224
A12: 10 | B12: 1969/PS.04.04/EKST/V/2026 | C12: Surat Teguran atas Tidak Sesuainya Penerapan Aspek Keselamatan dan Kesehatan Kerja(K3) yang berdampak pada Kecelakaan dan Citra Buruk PAM JAYA pada Masyarakat | D12: teguran berulang kepada ABJ atas pelanggaran K3 yang menyebabkan kecelakaan dan keluhan masyarakat, serta mewajibkan ABJ segera melakukan perbaikan, meningkatkan pengawasan, bertanggung jawab atas insiden, dan mencegah kejadian serupa terulang. | E12: HSE-Irsan/Suhendro | F12: 46224
A13: 11 | B13: 1970/PS.04.04/EKST/V/2026 | C13: Permintaan Komitmen atas Seluruh Fasilitas Baru Siap Dioperasikan Sesuai Ketentuan Dokumen Amandemen dan Pernyataan Kembali Perjanjian Kerja sama Bundling | D13: PAM JAYA menemukan kebocoran pada pipa Trunk Main P5 SPAM Buaran 3 Hilir setelah pekerjaan dinyatakan selesai oleh PT ABJ. Oleh karena itu, PT ABJ diminta memperbaiki kebocoran, memastikan kualitas pekerjaan agar tidak terulang, dan mempercepat operasional fasilitas untuk mendukung target cakupan layanan air minum 100%. | E13: PMO TM-Puji R | F13: 46224
A14: 12 | B14: e-80724/PP.01.02 | C14: Teguran atas Ketidaksesuaian Pelaksanaan Pengurugan dan Perbaikan Bekas Galian yang Berdampak pada Gangguan Lalu Lintas dan Keterlambatan Penyelesaian Proyek pada Program Infill SPAM Buaran III | D14: PAM JAYA menemukan 168 titik bekas galian yang belum diperbaiki sesuai standar, penerapan K3 yang belum memadai, gangguan lalu lintas, serta pekerjaan yang menimbulkan keluhan masyarakat dan pemberitaan negatif pada PAMJAYA (wilayah condet) | ABJ diminta untuk segera perbaikin hal tersebut | E14: HSE-Suhendro | F14: 46224
... A45: 43 | B45: e-83262/PS.04.01 | C45: Penyampaian Hasil Inspeksi Perawatan Peralatan di IPA Buaran | D45: dari hasil Inspeksi terjadwal perawatan alat di IPA Buaran 1, IPA Buaran 2, dan IPA Buaran 3 yang dilakukan tanggal 20 Mei 2026, Pamjaya menemukan 26 temuan, dan ABJ diminta menindaklanjuti dalam 14 hari kalender | E45: Produksi-Wahyudian | F45: 46224

Sheet Outgoing 2026
A1: No | B1: Nomor Surat | C1: Tanggal Surat | D1: Penerima | E1: Perihal | F1: Deskripsi | G1: Produksi/Project | H1: Lokasi | I1: Kategori | J1: Due Date | K1: Status | L1: DIC | M1: PIC | N1: Durasi | O1: Durasi (Hari) | Q1: =TODAY() -> 46218
A2: 1 | B2: ABJ/DIR/EKS/01.26/0001 | C2: 46024 | D2: PAM JAYA | E2: Usulan Diskusi Mengenai Konsultan Independen atas Perhitungan Tagihan KBA | G2: Project | H2: Greenfield | I2: Keuangan, Pembayaran, Investasi | K2: Closed | L2: Compliance | M2: Indradi | N2: =DATEDIF(C2,$Q$1,"Y")&" tahun, "&DATEDIF(C2,$Q$1,"YM")&" bulan, "&DATEDIF(C2,$Q$1,"MD")&" hari" -> 0 tahun, 6 bulan, 13 hari | O2: =TODAY()-C2 -> 194
A3: 2 | B3: ABJ/DIR/EKS/01.26/0002 | C3: 46024 | D3: PAM JAYA | E3: Penyampaian Progres Penyelesaian Pekerjaan Program TOK 5 Oktober 2025 | G3: Project | H3: Greenfield | I3: Konstruksi Program Greenfield | K3: Info | L3: PGO | M3: Angelika | N3: =DATEDIF(C3,$Q$1,"Y")&" tahun, "&DATEDIF(C3,$Q$1,"YM")&" bulan, "&DATEDIF(C3,$Q$1,"MD")&" hari" -> 0 tahun, 6 bulan, 13 hari | O3: =TODAY()-C3 -> 194
A4: 3 | B4: ABJ/DIR/EKS/01.26/0003 | C4: 46024 | D4: PAM JAYA | E4: Pemasangan Pipa Ramset Pada Program Master Meter Binton | G4: Project | H4: Jatiluhur Hilir | I4: Konstruksi Program Greenfield | K4: Info | L4: PMO Infill | M4: Muhrojin | N4: =DATEDIF(C4,$Q$1,"Y")&" tahun, "&DATEDIF(C4,$Q$1,"YM")&" bulan, "&DATEDIF(C4,$Q$1,"MD")&" hari" -> 0 tahun, 6 bulan, 13 hari | O4: =TODAY()-C4 -> 194
A5: 4 | B5: ABJ/DIR/EKS/01.26/0004 | C5: 46024 | D5: KPI | E5: Permintaan Laporan Verifikasi KPI atas Program Rehabilitasi Proyek Greenfield (IPA Buaran III) | G5: Project | H5: Buaran 3 Hulu | I5: Administrasi & Dokumentasi | K5: Open | L5: Compliance | M5: Indradi | N5: =DATEDIF(C5,$Q$1,"Y")&" tahun, "&DATEDIF(C5,$Q$1,"YM")&" bulan, "&DATEDIF(C5,$Q$1,"MD")&" hari" -> 0 tahun, 6 bulan, 13 hari | O5: =TODAY()-C5 -> 194
A6: 5 | B6: ABJ/DIR/EKS/01.26/0009 | C6: 46027 | D6: Lurah Rawamangun | E6: Surat Pemberitahuan | G6: Project | H6: Greenfield | I6: Konstruksi Program Greenfield | K6: Info | L6: PMO TM | M6: Suci | N6: =DATEDIF(C6,$Q$1,"Y")&" tahun, "&DATEDIF(C6,$Q$1,"YM")&" bulan, "&DATEDIF(C6,$Q$1,"MD")&" hari" -> 0 tahun, 6 bulan, 10 hari | O6: =TODAY()-C6 -> 191
A7: 6 | B7: ABJ/DIR/EKS/01.26/0010 | C7: 46027 | D7: PAM JAYA | E7: Tagihan Air Curah Perjanjian Brownfield – Periode Desember 2025 | G7: Corporate | H7: Corporate | I7: Keuangan, Pembayaran, Investasi | K7: Closed | L7: Compliance | M7: Indradi | N7: =DATEDIF(C7,$Q$1,"Y")&" tahun, "&DATEDIF(C7,$Q$1,"YM")&" bulan, "&DATEDIF(C7,$Q$1,"MD")&" hari" -> 0 tahun, 6 bulan, 10 hari | O7: =TODAY()-C7 -> 191
A8: 7 | B8: ABJ/DIR/EKS/01.26/0011 | C8: 46027 | D8: PAM JAYA | E8: Tagihan Air Curah Perjanjian Greenfield - Periode Desember 2025 | G8: Corporate | H8: Corporate | I8: Keuangan, Pembayaran, Investasi | K8: Closed | L8: Compliance | M8: Indradi | N8: =DATEDIF(C8,$Q$1,"Y")&" tahun, "&DATEDIF(C8,$Q$1,"YM")&" bulan, "&DATEDIF(C8,$Q$1,"MD")&" hari" -> 0 tahun, 6 bulan, 10 hari | O8: =TODAY()-C8 -> 191
A9: 8 | B9: ABJ/DIR/EKS/01.26/0012 | C9: 46027 | D9: PAM JAYA | E9: Pembaharuan Informasi Dokumen Persyaratan Penyelesaian Pekerjaan Fasilitas Distribusi Baru Paket Kedua TOK Oktober 2025 | G9: Project | H9: Greenfield | I9: Administrasi & Dokumentasi | K9: Info | L9: PGO | M9: Angelika | N9: =DATEDIF(C9,$Q$1,"Y")&" tahun, "&DATEDIF(C9,$Q$1,"YM")&" bulan, "&DATEDIF(C9,$Q$1,"MD")&" hari" -> 0 tahun, 6 bulan, 10 hari | O9: =TODAY()-C9 -> 191
A10: 9 | B10: ABJ/DIR/EKS/01.26/0013 | C10: 46027 | D10: PAM JAYA | E10: Laporan Bulanan Kualitas Air Baku dan Air Curah Periode Desember 2025 | G10: Produksi | H10: ALL WTP | I10: Monitoring & Pelaporan | K10: Info | L10: WQA | M10: Novi | N10: =DATEDIF(C10,$Q$1,"Y")&" tahun, "&DATEDIF(C10,$Q$1,"YM")&" bulan, "&DATEDIF(C10,$Q$1,"MD")&" hari" -> 0 tahun, 6 bulan, 10 hari | O10: =TODAY()-C10 -> 191
A11: 10 | B11: ABJ/DIR/EKS/01.26/0014 | C11: 46027 | D11: Direktur Jenderal Administrasi Hukum Umum cq. Direktur Badan Usaha Kementerian Hukum | E11: Permohonan Perbaikan Data Email dan Nomor Telepon PT AIR BERSIH JAKARTA | G11: Corporate | H11: Corporate | I11: Kontrak & Legal | K11: Info | L11: Legal - Moya | M11: Angelina | N11: =DATEDIF(C11,$Q$1,"Y")&" tahun, "&DATEDIF(C11,$Q$1,"YM")&" bulan, "&DATEDIF(C11,$Q$1,"MD")&" hari" -> 0 tahun, 6 bulan, 10 hari | O11: =TODAY()-C11 -> 191
A12: 11 | B12: ABJ/DIR/EKS/01.26/0015 | C12: 46028 | D12: Bank OCBC NISP, Tbk - Agency & Trust Services | E12: Penyampaian Salinan Asli Polis Asuransi | G12: Corporate | H12: Corporate | I12: Keuangan, Pembayaran, Investasi | K12: Info | L12: Finance | M12: Nurul S | N12: =DATEDIF(C12,$Q$1,"Y")&" tahun, "&DATEDIF(C12,$Q$1,"YM")&" bulan, "&DATEDIF(C12,$Q$1,"MD")&" hari" -> 0 tahun, 6 bulan, 9 hari | O12: =TODAY()-C12 -> 190
A13: 12 | B13: ABJ/DIR/EKS/01.26/0016 | C13: 46028 | D13: PT Bank Central Asia Tbk | E13: Permohonan Penghapusan Lampiran 6 Step-In dalam Persyaratan Lebih Lanjut | G13: Corporate | H13: Corporate | I13: Kontrak & Legal | K13: Info | L13: Legal | M13: Bahtera N | N13: =DATEDIF(C13,$Q$1,"Y")&" tahun, "&DATEDIF(C13,$Q$1,"YM")&" bulan, "&DATEDIF(C13,$Q$1,"MD")&" hari" -> 0 tahun, 6 bulan, 9 hari | O13: =TODAY()-C13 -> 190
... A144: 144 | B144: ABJ/DIR/EKS/02.26/0150 | C144: 46065 | D144: PAM JAYA | E144: Pembatalan Program Basri | G144: Project | H144: Jatiluhur Hilir | I144: Konstruksi Program Greenfield | K144: Info | L144: PMO Infill | M144: Aan | N144: =DATEDIF(C144,$Q$1,"Y")&" tahun, "&DATEDIF(C144,$Q$1,"YM")&" bulan, "&DATEDIF(C144,$Q$1,"MD")&" hari" -> 0 tahun, 5 bulan, 3 hari | O144: =TODAY()-C144 -> 153
A145: 145 | B145: ABJ/DIR/EKS/02.26/0151 | C145: 46065 | K145: Info | N145: =DATEDIF(C145,$Q$1,"Y")&" tahun, "&DATEDIF(C145,$Q$1,"YM")&" bulan, "&DATEDIF(C145,$Q$1,"MD")&" hari" -> 0 tahun, 5 bulan, 3 hari | O145: =TODAY()-C145 -> 153
A146: 146 | B146: ABJ/DIR/EKS/02.26/0152 | C146: 46066 | D146: PAM JAYA | E146: Tanggapan Atas Surat PAM JAYA No. e-69891.TK.03.04 Perihal Dokumen Risk Register Brownfield 2026 dan Risk Register New Connection 2026 | G146: Project | H146: Greenfield | I146: Manajemen Risiko | K146: Info | L146: QMS | M146: Dio | N146: =DATEDIF(C146,$Q$1,"Y")&" tahun, "&DATEDIF(C146,$Q$1,"YM")&" bulan, "&DATEDIF(C146,$Q$1,"MD")&" hari" -> 0 tahun, 5 bulan, 2 hari | O146: =TODAY()-C146 -> 152
A147: 147 | B147: ABJ/DIR/EKS/02.26/0153 | C147: 46066 | D147: PT. Bestindo Putra Mandiri | E147: Pernyataan Pembayaran Biaya Penggunaan Air | G147: Project | H147: Greenfield | I147: Keuangan, Pembayaran, Investasi | K147: Info | L147: Finance | M147: Nurul S | N147: =DATEDIF(C147,$Q$1,"Y")&" tahun, "&DATEDIF(C147,$Q$1,"YM")&" bulan, "&DATEDIF(C147,$Q$1,"MD")&" hari" -> 0 tahun, 5 bulan, 2 hari | O147: =TODAY()-C147 -> 152
A148: 148 | B148: ABJ/DIR/EKS/02.26/0154 | C148: 46066 | D148: PAM JAYA | E148: Proses Pembahasan Alur untuk Pengakuan Investasi SL dan Cyble | G148: Project | H148: Greenfield | I148: Sambungan Langsung | K148: Info | L148: PMO NC | M148: A. Levi | N148: =DATEDIF(C148,$Q$1,"Y")&" tahun, "&DATEDIF(C148,$Q$1,"YM")&" bulan, "&DATEDIF(C148,$Q$1,"MD")&" hari" -> 0 tahun, 5 bulan, 2 hari | O148: =TODAY()-C148 -> 152
A149: 149 | B149: ABJ/DIR/EKS/02.26/0155 | C149: 46066 | D149: PAM JAYA | E149: Penjelasan Kondisi Eksternal Penyebab Keterlambatan Pemasangan dan Pengembalian Field Activity (“FA”) Sambungan Langsung (“SL”) as per 13 Februari 2026 | G149: Project | H149: Greenfield | I149: Sambungan Langsung | K149: Info | L149: PMO NC | M149: A. Levi | N149: =DATEDIF(C149,$Q$1,"Y")&" tahun, "&DATEDIF(C149,$Q$1,"YM")&" bulan, "&DATEDIF(C149,$Q$1,"MD")&" hari" -> 0 tahun, 5 bulan, 2 hari | O149: =TODAY()-C149 -> 152
A150: 150 | B150: ABJ/DIR/EKS/02.26/0156 | C150: 46066 | D150: PAM JAYA | E150: Penyampaian Informasi Terkait Tagihan Air Curah Perjanjian Brownfield dan Greenfield – Periode Penagihan Januari 2026 | G150: Project | H150: Project | I150: Keuangan, Pembayaran, Investasi | K150: Closed | L150: Compliance | M150: Indradi | N150: =DATEDIF(C150,$Q$1,"Y")&" tahun, "&DATEDIF(C150,$Q$1,"YM")&" bulan, "&DATEDIF(C150,$Q$1,"MD")&" hari" -> 0 tahun, 5 bulan, 2 hari | O150: =TODAY()-C150 -> 152
A151: 151 | B151: ABJ/DIR/EKS/02.26/0157 | C151: 46066 | D151: PAM JAYA | E151: Penyampaian Dokumen Pendukung Program Konstruksi SPAM Karian Hilir | G151: Project | H151: Greenfield | I151: Konstruksi Program Greenfield | K151: Info | L151: PMO TM | M151: Suci | N151: =DATEDIF(C151,$Q$1,"Y")&" tahun, "&DATEDIF(C151,$Q$1,"YM")&" bulan, "&DATEDIF(C151,$Q$1,"MD")&" hari" -> 0 tahun, 5 bulan, 2 hari | O151: =TODAY()-C151 -> 152
A152: 152 | B152: ABJ/DIR/EKS/02.26/0158 | C152: 46071 | D152: PAM JAYA | E152: Alternatif Water Meter ITRON Aquadis 15mm Menggantikan Tipe Water Meter Multimag 15mm | G152: Project | H152: Greenfield | I152: Sambungan Langsung | K152: Info | L152: PMO NC | M152: A. Levi | N152: =DATEDIF(C152,$Q$1,"Y")&" tahun, "&DATEDIF(C152,$Q$1,"YM")&" bulan, "&DATEDIF(C152,$Q$1,"MD")&" hari" -> 0 tahun, 4 bulan, 27 hari | O152: =TODAY()-C152 -> 147
A153: 153 | B153: ABJ/DIR/EKS/02.26/0159 | C153: 46071 | D153: PT. Bestindo Putra Mandiri | E153: Surat Teguran BPM - Updating Stok Material | G153: Project | H153: Greenfield | I153: Konstruksi Program Greenfield | K153: Info | L153: PMO NC | M153: A. Levi | N153: =DATEDIF(C153,$Q$1,"Y")&" tahun, "&DATEDIF(C153,$Q$1,"YM")&" bulan, "&DATEDIF(C153,$Q$1,"MD")&" hari" -> 0 tahun, 4 bulan, 27 hari | O153: =TODAY()-C153 -> 147
A154: 154 | B154: ABJ/DIR/EKS/02.26/0160 | C154: 46071 | D154: PAM JAYA | E154: Tanggapan PJ e 71125 PP 01 02 Teguran Keterlambatan Realisasi SL Desember 2025 | G154: Project | H154: Greenfield | I154: Sambungan Langsung | K154: Info | L154: PMO NC | M154: A. Levi | N154: =DATEDIF(C154,$Q$1,"Y")&" tahun, "&DATEDIF(C154,$Q$1,"YM")&" bulan, "&DATEDIF(C154,$Q$1,"MD")&" hari" -> 0 tahun, 4 bulan, 27 hari | O154: =TODAY()-C154 -> 147
A155: 155 | B155: ABJ/DIR/EKS/02.26/0161 | C155: 46071 | D155: Keluarahan Bambu Apus | E155: Pemberitahuan Kegiatan Pekerjaan Galian Pipa di wilayah Keluarahan Bambu Apus | G155: Project | H155: Greenfield | I155: Koordinasi & Sosialisasi | K155: Info | L155: PMO TM | M155: Suci | N155: =DATEDIF(C155,$Q$1,"Y")&" tahun, "&DATEDIF(C155,$Q$1,"YM")&" bulan, "&DATEDIF(C155,$Q$1,"MD")&" hari" -> 0 tahun, 4 bulan, 27 hari | O155: =TODAY()-C155 -> 147
A156: 156 | B156: ABJ/DIR/EKS/02.26/0162 | C156: 46071 | D156: Keluarahan Setu | E156: Pemberitahuan Kegiatan Pekerjaan Galian Pipa di wilayah Keluarahan Setu | G156: Project | H156: Greenfield | I156: Koordinasi & Sosialisasi | K156: Info | L156: PMO TM | M156: Suci | N156: =DATEDIF(C156,$Q$1,"Y")&" tahun, "&DATEDIF(C156,$Q$1,"YM")&" bulan, "&DATEDIF(C156,$Q$1,"MD")&" hari" -> 0 tahun, 4 bulan, 27 hari | O156: =TODAY()-C156 -> 147
A157: 157 | B157: ABJ/DIR/EKS/02.26/0163 | C157: 46071 | D157: Kecamatan Pademangan | E157: Pemberitahuan Kegiatan Pekerjaan Galian Pipa di wilayah Kecamatan Pademangan | G157: Project | H157: Greenfield | I157: Koordinasi & Sosialisasi | K157: Info | L157: PMO TM | M157: Suci | N157: =DATEDIF(C157,$Q$1,"Y")&" tahun, "&DATEDIF(C157,$Q$1,"YM")&" bulan, "&DATEDIF(C157,$Q$1,"MD")&" hari" -> 0 tahun, 4 bulan, 27 hari | O157: =TODAY()-C157 -> 147
... A294: 294 | B294: ABJ/DIR/EKS/03.26/0302 | C294: 46098 | D294: PAM JAYA | E294: Undangan Uji Komisioning SPAM Buaran III Hilir – Trunkmain (P6 dan P11) | G294: Project | H294: Buaran 3 Hilir | I294: Konstruksi Program Greenfield | K294: Info | L294: PMO TM | M294: Puji R | N294: =DATEDIF(C294,$Q$1,"Y")&" tahun, "&DATEDIF(C294,$Q$1,"YM")&" bulan, "&DATEDIF(C294,$Q$1,"MD")&" hari" -> 0 tahun, 3 bulan, 28 hari | O294: =TODAY()-C294 -> 120
A295: 295 | B295: ABJ/DIR/EKS/03.26/0303 | C295: 46098 | D295: PT. Bina Lestari Lingkungan Sejahtera | E295: Permohonan Bantuan BLSS Dalam Percepatan Verifikasi Dokumen | G295: Corporate | I295: Koordinasi & Sosialisasi | K295: Info | L295: PGO | M295: Lusian F | N295: =DATEDIF(C295,$Q$1,"Y")&" tahun, "&DATEDIF(C295,$Q$1,"YM")&" bulan, "&DATEDIF(C295,$Q$1,"MD")&" hari" -> 0 tahun, 3 bulan, 28 hari | O295: =TODAY()-C295 -> 120
A296: 296 | B296: ABJ/DIR/EKS/03.26/0304 | C296: 46098 | D296: PAM JAYA | E296: Pemberitahuan Pelaksanaan Pekerjaan Masa Libur Lebaran - Proyek Karian Serpong Trunk Main Pesanggrahan TMPSG 04 | G296: Project | H296: Karian Serpong Hilir | I296: Konstruksi Program Greenfield | K296: Info | L296: PMO TM | M296: Suci | N296: =DATEDIF(C296,$Q$1,"Y")&" tahun, "&DATEDIF(C296,$Q$1,"YM")&" bulan, "&DATEDIF(C296,$Q$1,"MD")&" hari" -> 0 tahun, 3 bulan, 28 hari | O296: =TODAY()-C296 -> 120
A297: 297 | B297: ABJ/DIR/EKS/03.26/0305 | C297: 46098 | D297: PAM JAYA | K297: Info | N297: =DATEDIF(C297,$Q$1,"Y")&" tahun, "&DATEDIF(C297,$Q$1,"YM")&" bulan, "&DATEDIF(C297,$Q$1,"MD")&" hari" -> 0 tahun, 3 bulan, 28 hari | O297: =TODAY()-C297 -> 120
A298: 298 | B298: ABJ/DIR/EKS/03.26/0306 | C298: 46098 | D298: Agen Fasilitas PT. BCA | E298: Permohonan Perpanjangan Periode Ketersediaan untuk Fasilitas E1 | G298: Corporate | H298: Corporate | I298: Kontrak & Legal | K298: Info | L298: Legal | M298: Bahtera N | N298: =DATEDIF(C298,$Q$1,"Y")&" tahun, "&DATEDIF(C298,$Q$1,"YM")&" bulan, "&DATEDIF(C298,$Q$1,"MD")&" hari" -> 0 tahun, 3 bulan, 28 hari | O298: =TODAY()-C298 -> 120
A299: 299 | B299: ABJ/DIR/EKS/03.26/0307 | C299: 46098 | D299: PAM JAYA | E299: Penjelasan Kondisi Eksternal Penyebab Keterlambatan Pemasangan dan Pengembalian Field Activity (“FA”) Sambungan Langsung (“SL”) as per 17 Maret 2026 | G299: Project | H299: Greenfield | I299: Sambungan Langsung | K299: Info | L299: PMO NC | M299: Angelika | N299: =DATEDIF(C299,$Q$1,"Y")&" tahun, "&DATEDIF(C299,$Q$1,"YM")&" bulan, "&DATEDIF(C299,$Q$1,"MD")&" hari" -> 0 tahun, 3 bulan, 28 hari | O299: =TODAY()-C299 -> 120
A300: 300 | B300: ABJ/DIR/EKS/03.26/0308 | C300: 46098 | D300: PT Bestindo Putra Mandiri | E300: Teguran Ketidakpatuhan Pekerjaan Harian Pemasangan Cyble | G300: Project | H300: Greenfield | I300: Sambungan Langsung | K300: Info | L300: PMO NC | M300: Angelika | N300: =DATEDIF(C300,$Q$1,"Y")&" tahun, "&DATEDIF(C300,$Q$1,"YM")&" bulan, "&DATEDIF(C300,$Q$1,"MD")&" hari" -> 0 tahun, 3 bulan, 28 hari | O300: =TODAY()-C300 -> 120
A301: 301 | B301: ABJ/DIR/EKS/03.26/0309 | C301: 46098 | D301: PAM JAYA | K301: Info | N301: =DATEDIF(C301,$Q$1,"Y")&" tahun, "&DATEDIF(C301,$Q$1,"YM")&" bulan, "&DATEDIF(C301,$Q$1,"MD")&" hari" -> 0 tahun, 3 bulan, 28 hari | O301: =TODAY()-C301 -> 120
A302: 302 | B302: ABJ/DIR/EKS/03.26/0310 | C302: 46099 | D302: PAM JAYA | E302: Penyampaian Informasi Proyek SPAM Jatiluhur Hilir - Program MCD Jatipadang | G302: Project | H302: Jatiluhur Hilir | I302: Konstruksi Program Greenfield | K302: Info | L302: PMO Infill | M302: Danny L | N302: =DATEDIF(C302,$Q$1,"Y")&" tahun, "&DATEDIF(C302,$Q$1,"YM")&" bulan, "&DATEDIF(C302,$Q$1,"MD")&" hari" -> 0 tahun, 3 bulan, 27 hari | O302: =TODAY()-C302 -> 119
A303: 303 | B303: ABJ/DIR/EKS/03.26/0311 | C303: 46099 | D303: PAM JAYA | E303: Pemberitahuan Perubahan Jadwal Flushing - SPAM Buaran Hilir Paket P6 dan P11 | G303: Project | H303: Buaran 3 Hilir | I303: Konstruksi Program Greenfield | K303: Info | L303: PMO TM | M303: Puji R | N303: =DATEDIF(C303,$Q$1,"Y")&" tahun, "&DATEDIF(C303,$Q$1,"YM")&" bulan, "&DATEDIF(C303,$Q$1,"MD")&" hari" -> 0 tahun, 3 bulan, 27 hari | O303: =TODAY()-C303 -> 119
A304: 304 | B304: ABJ/DIR/EKS/03.26/0313 | C304: 46106 | D304: PAM JAYA | E304: Penyampaian Laporan Penyelesaian Uji Komisioning PC 162 Centex Gg Jengki dan PC 162 Hanjuang | G304: Project | H304: Greenfield | I304: Konstruksi Program Greenfield | K304: Info | L304: PMO Infill | M304: Topan | N304: =DATEDIF(C304,$Q$1,"Y")&" tahun, "&DATEDIF(C304,$Q$1,"YM")&" bulan, "&DATEDIF(C304,$Q$1,"MD")&" hari" -> 0 tahun, 3 bulan, 20 hari | O304: =TODAY()-C304 -> 112
A305: 305 | B305: ABJ/DIR/EKS/03.26/0314 | C305: 46106 | D305: PAM JAYA | E305: Tanggapan Surat PAM JAYA Nomor 1186/PS.04.04/EKST/III/2026 Mengenai Pembayaran atas Realisasi Kontrak Berbasis Angsuran (KBA) Tahun 2025 | G305: Project | H305: Greenfield | I305: Keuangan, Pembayaran, Investasi | K305: Closed | L305: Compliance | M305: A. Levi | N305: =DATEDIF(C305,$Q$1,"Y")&" tahun, "&DATEDIF(C305,$Q$1,"YM")&" bulan, "&DATEDIF(C305,$Q$1,"MD")&" hari" -> 0 tahun, 3 bulan, 20 hari | O305: =TODAY()-C305 -> 112
A306: 306 | B306: ABJ/DIR/EKS/03.26/0315 | C306: 46106 | D306: PAM JAYA | E306: Permintaan Percepatan Persetujuan Program Brownfield Sebagai Pemenuhan ISO 14001:2015 | G306: Project | H306: Cyclical | I306: Perencanaan Program Rehabilitasi | K306: Open | L306: PMO Cyclical | M306: Agus H | N306: =DATEDIF(C306,$Q$1,"Y")&" tahun, "&DATEDIF(C306,$Q$1,"YM")&" bulan, "&DATEDIF(C306,$Q$1,"MD")&" hari" -> 0 tahun, 3 bulan, 20 hari | O306: =TODAY()-C306 -> 112
...

Sheet Incoming 2026
A1: No | B1: Nomor Surat | C1: Tanggal Diterima | D1: Tanggal Surat | E1: Pengirim | F1: Perihal | G1: Deskripsi | H1: Produksi/Project | I1: Lokasi | J1: Kategori | K1: Due Date | L1: Status | M1: Level Status | N1: DIC | O1: PIC | P1: Durasi | Q1: Durasi (hari) | S1: Durasi Keterlambatan | T1: Durasi Deadline | U1: Keterangan | W1: =TODAY() -> 46218
A2: 1 | B2: 144/SCI-KPI/I/2026 | C2: 46027 | D2: 46024 | E2: KPI - Sucofindo | F2: Tanggapan atas Surat PT Air Bersih Jakarta No. ABJ/DIR/EKS/12.25/1126 Tentang Penyampaian Laporan Penyelesaian Uji Komisioning Project Greenfield - SPAM Karian Serpong Hilir Program Arman, Puspa, Porto | G2: Dokumen yang belum lengkap agar dilengkapi pada saat MC100 | H2: Project | I2: Karian Serpong Hilir | J2: Konstruksi Program Greenfield | L2: Info | M2: Info | N2: PMO Infill | O2: Ervin Y | P2: =DATEDIF(C2,$W$1,"Y")&" tahun, "&DATEDIF(C2,$W$1,"YM")&" bulan, "&DATEDIF(C2,$W$1,"MD")&" hari" -> 0 tahun, 6 bulan, 10 hari | Q2: =DATEDIF(C2,Summary!$A$1,"d") -> 191 | S2: {=_xlfn.IFS(Q2<=T2,T2,Q2<=T2*2,T2*2,Q2<=T2*3,T2*3,Q2>T2*3,">"&T2*3)} -> Info | T2: {=_xlfn.IFS(M2="Level 1",7,M2="Level 2",14,M2="Level 3","30",M2="Info","Info",M2="Closed","Closed")} -> Info
A3: 2 | B3: e-70214/PP.00.02 | C3: 46028 | D3: 46009 | E3: PAM JAYA | F3: Pemutakhiran Desain Akhir JDU JDB JDL dan SL Proyek Greenfield Regional Barat, Selatan, Utara, Pusat | G3: PAM JAYA meminta ABJ untuk melakukan survey sesuai lokasi pada surat terlampir | H3: Project | I3: Greenfield | J3: Perencanaan Program Greenfield | L3: Open | M3: Level 2 | N3: PMO Infill | O3: Danny L | P3: =DATEDIF(C3,$W$1,"Y")&" tahun, "&DATEDIF(C3,$W$1,"YM")&" bulan, "&DATEDIF(C3,$W$1,"MD")&" hari" -> 0 tahun, 6 bulan, 9 hari | Q3: =DATEDIF(C3,Summary!$A$1,"d") -> 190 | R3: lewat 30d | S3: {=_xlfn.IFS(Q3<=T3,T3,Q3<=T3*2,T3*2,Q3<=T3*3,T3*3,Q3>T3*3,">"&T3*3)} -> >42 | T3: {=_xlfn.IFS(M3="Level 1",7,M3="Level 2",14,M3="Level 3","30",M3="Info","Info",M3="Closed","Closed")} -> 14
A4: 3 | B4: e-70215/PS.00.04 | C4: 46028 | D4: 46008 | E4: PAM JAYA | F4: Permintaan Bukti Penyimpanan Dokumen | G4: PAM JAYA meminta bukti penyimpanan dokumen selambatnya 7 hari sejak surat diterima | H4: Corporate | I4: Corporate | J4: Administrasi & Dokumentasi | L4: Closed | M4: Closed | N4: Compliance | O4: Indradi | P4: =DATEDIF(C4,$W$1,"Y")&" tahun, "&DATEDIF(C4,$W$1,"YM")&" bulan, "&DATEDIF(C4,$W$1,"MD")&" hari" -> 0 tahun, 6 bulan, 9 hari | Q4: =DATEDIF(C4,Summary!$A$1,"d") -> 190 | S4: {=_xlfn.IFS(Q4<=T4,T4,Q4<=T4*2,T4*2,Q4<=T4*3,T4*3,Q4>T4*3,">"&T4*3)} -> Closed | T4: {=_xlfn.IFS(M4="Level 1",7,M4="Level 2",14,M4="Level 3","30",M4="Info","Info",M4="Closed","Closed")} -> Closed | U4: Dibalas surat ABJ/DIR/EKS/01.26/0044
A5: 4 | B5: e-70217/PP.00.02 | C5: 46028 | D5: 46013 | E5: PAM JAYA | F5: Percepatan Pelaksanaan Program JDU+JDB+JDL dan Sambungan Langsung di Area Prioritas Regional Utara (Pantai Mutiara, Kp. Muka, Kp. Kerang Hijau Muara Angke) | G5: PAM JAYA meminta percepatan pekerjaan dan SL pada lokasi surat terlampir | H5: Project | I5: Greenfield | J5: Sambungan Langsung | L5: Open | M5: Level 2 | N5: PMO Infill | O5: Danny L | P5: =DATEDIF(C5,$W$1,"Y")&" tahun, "&DATEDIF(C5,$W$1,"YM")&" bulan, "&DATEDIF(C5,$W$1,"MD")&" hari" -> 0 tahun, 6 bulan, 9 hari | Q5: =DATEDIF(C5,Summary!$A$1,"d") -> 190 | R5: lewat 30d | S5: {=_xlfn.IFS(Q5<=T5,T5,Q5<=T5*2,T5*2,Q5<=T5*3,T5*3,Q5>T5*3,">"&T5*3)} -> >42 | T5: {=_xlfn.IFS(M5="Level 1",7,M5="Level 2",14,M5="Level 3","30",M5="Info","Info",M5="Closed","Closed")} -> 14
A6: 5 | B6: e-70229/PP.00.02 | C6: 46028 | D6: 46013 | E6: PAM JAYA | F6: Pemutakhiran Desain Akhir Proyek Greenfield IPA Portable Semanan | G6: PAM JAYA meminta untuk dilakukan survei bersama pada lokasi terlampir | H6: Project | I6: Greenfield | J6: Perencanaan Program Greenfield | L6: Open | M6: Level 2 | N6: PMO Infill | O6: Danny L | P6: =DATEDIF(C6,$W$1,"Y")&" tahun, "&DATEDIF(C6,$W$1,"YM")&" bulan, "&DATEDIF(C6,$W$1,"MD")&" hari" -> 0 tahun, 6 bulan, 9 hari | Q6: =DATEDIF(C6,Summary!$A$1,"d") -> 190 | R6: lewat 30d | S6: {=_xlfn.IFS(Q6<=T6,T6,Q6<=T6*2,T6*2,Q6<=T6*3,T6*3,Q6>T6*3,">"&T6*3)} -> >42 | T6: {=_xlfn.IFS(M6="Level 1",7,M6="Level 2",14,M6="Level 3","30",M6="Info","Info",M6="Closed","Closed")} -> 14
A7: 6 | B7: e-68122/PP.00.02 | C7: 46028 | D7: 45987 | E7: PAM JAYA | F7: Pemutakhiran Desain Akhir JDU JDB JDL dan SL Proyek Greenfield Corporate Customer Regional Timur | G7: PAM JAYA meminta untuk dilakukan survei bersama pada lokasi di surat terlampir | H7: Project | I7: Greenfield | J7: Perencanaan Program Greenfield | L7: Open | M7: Level 2 | N7: PMO Infill | O7: Danny L | P7: =DATEDIF(C7,$W$1,"Y")&" tahun, "&DATEDIF(C7,$W$1,"YM")&" bulan, "&DATEDIF(C7,$W$1,"MD")&" hari" -> 0 tahun, 6 bulan, 9 hari | Q7: =DATEDIF(C7,Summary!$A$1,"d") -> 190 | R7: lewat 30d | S7: {=_xlfn.IFS(Q7<=T7,T7,Q7<=T7*2,T7*2,Q7<=T7*3,T7*3,Q7>T7*3,">"&T7*3)} -> >42 | T7: {=_xlfn.IFS(M7="Level 1",7,M7="Level 2",14,M7="Level 3","30",M7="Info","Info",M7="Closed","Closed")} -> 14
A8: 7 | B8: e-70620/PP.00.02 | C8: 46028 | E8: PAM JAYA | F8: Pemutakhiran Desain Akhir JDU JDB JDL dan SL Proyek Greenfield Regional Utara dan Selatan | H8: Project | I8: Greenfield | J8: Perencanaan Program Greenfield | L8: Open | M8: Level 2 | N8: PMO Infill | O8: Danny L | P8: =DATEDIF(C8,$W$1,"Y")&" tahun, "&DATEDIF(C8,$W$1,"YM")&" bulan, "&DATEDIF(C8,$W$1,"MD")&" hari" -> 0 tahun, 6 bulan, 9 hari | Q8: =DATEDIF(C8,Summary!$A$1,"d") -> 190 | R8: lewat 30d | S8: {=_xlfn.IFS(Q8<=T8,T8,Q8<=T8*2,T8*2,Q8<=T8*3,T8*3,Q8>T8*3,">"&T8*3)} -> >42 | T8: {=_xlfn.IFS(M8="Level 1",7,M8="Level 2",14,M8="Level 3","30",M8="Info","Info",M8="Closed","Closed")} -> 14
A9: 8 | B9: 4720/PP.01.03/EKST/XII/2025 | C9: 46028 | D9: 46022 | E9: PAM JAYA | F9: Permintaan Pemenuhan Kewajiban Penyelesaian Paket Pekerjaan Kedua Proyek Greenfield pada saat Tanggal Operasi Komersial atau 5 Oktober 2025 | G9: Informasi project TOK 5 Oktober dan PAM JAYA meminta untuk memenuhi seluruh pekerjaan dan seluruh dokumen | H9: Project | I9: Greenfield | J9: Konstruksi Program Greenfield | L9: Info | M9: Info | N9: PMO Infill | O9: Danny L | P9: =DATEDIF(C9,$W$1,"Y")&" tahun, "&DATEDIF(C9,$W$1,"YM")&" bulan, "&DATEDIF(C9,$W$1,"MD")&" hari" -> 0 tahun, 6 bulan, 9 hari | Q9: =DATEDIF(C9,Summary!$A$1,"d") -> 190 | S9: {=_xlfn.IFS(Q9<=T9,T9,Q9<=T9*2,T9*2,Q9<=T9*3,T9*3,Q9>T9*3,">"&T9*3)} -> Info | T9: {=_xlfn.IFS(M9="Level 1",7,M9="Level 2",14,M9="Level 3","30",M9="Info","Info",M9="Closed","Closed")} -> Info
A10: 9 | B10: e-70216/PS.04.03 | C10: 46028 | D10: 46007 | E10: PAM JAYA | F10: Konfirmasi Perpanjangan Polis Asuransi Project Brownfield & Greenfield | G10: Konfirmasi rencana perpanjangan polis dalam jangka waktu 3 hari kalender | H10: Project | I10: Project | J10: Kontrak & Legal | L10: Closed | M10: Closed | N10: Finance | O10: Nurul S | P10: =DATEDIF(C10,$W$1,"Y")&" tahun, "&DATEDIF(C10,$W$1,"YM")&" bulan, "&DATEDIF(C10,$W$1,"MD")&" hari" -> 0 tahun, 6 bulan, 9 hari | Q10: =DATEDIF(C10,Summary!$A$1,"d") -> 190 | S10: {=_xlfn.IFS(Q10<=T10,T10,Q10<=T10*2,T10*2,Q10<=T10*3,T10*3,Q10>T10*3,">"&T10*3)} -> Closed | T10: {=_xlfn.IFS(M10="Level 1",7,M10="Level 2",14,M10="Level 3","30",M10="Info","Info",M10="Closed","Closed")} -> Closed | U10: Dibalas Surat ABJ/DIR/EKS/01.26/0046
A11: 10 | B11: 4719/PP.01.02/EKST/XII/2025 | C11: 46028 | D11: 46022 | E11: PAM JAYA | F11: Teguran terhadap Pengawasan Konsultan Pengawas Independen pada Dokumen Amandemen dan Pernyataan kembali Perjanjian Kerjasama Bundling | G11: Surat PAM JAYA kepada KPI SCI terkait teguran terhadap pengawasan pekerjaan, HSE, dan dokumentasi bahwa KPI belum optimal dalam peran sebagai Konsultan Pengawas Independen | H11: Project | I11: Project | J11: Kontrak & Legal | L11: Info | M11: Info | N11: Compliance | O11: Indradi | P11: =DATEDIF(C11,$W$1,"Y")&" tahun, "&DATEDIF(C11,$W$1,"YM")&" bulan, "&DATEDIF(C11,$W$1,"MD")&" hari" -> 0 tahun, 6 bulan, 9 hari | Q11: =DATEDIF(C11,Summary!$A$1,"d") -> 190 | S11: {=_xlfn.IFS(Q11<=T11,T11,Q11<=T11*2,T11*2,Q11<=T11*3,T11*3,Q11>T11*3,">"&T11*3)} -> Info | T11: {=_xlfn.IFS(M11="Level 1",7,M11="Level 2",14,M11="Level 3","30",M11="Info","Info",M11="Closed","Closed")} -> Info
A12: 11 | B12: e-70362/PM.01.00 | C12: 46028 | D12: 46007 | E12: PAM JAYA | F12: Permohonan Pemasangan Sambungan Langsung Air Minum Perpipaan di area Halim Perdana Kusuma | G12: Surat PAM JAYA kepada Komandan Pangkalan TNI AU perihal pemasangan SL di area Halim | H12: Project | I12: Greenfield | J12: Sambungan Langsung | L12: Info | M12: Info | N12: PMO NC | O12: A. Levi | P12: =DATEDIF(C12,$W$1,"Y")&" tahun, "&DATEDIF(C12,$W$1,"YM")&" bulan, "&DATEDIF(C12,$W$1,"MD")&" hari" -> 0 tahun, 6 bulan, 9 hari | Q12: =DATEDIF(C12,Summary!$A$1,"d") -> 190 | S12: {=_xlfn.IFS(Q12<=T12,T12,Q12<=T12*2,T12*2,Q12<=T12*3,T12*3,Q12>T12*3,">"&T12*3)} -> Info | T12: {=_xlfn.IFS(M12="Level 1",7,M12="Level 2",14,M12="Level 3","30",M12="Info","Info",M12="Closed","Closed")} -> Info
A13: 12 | B13: 012/S/DIR/BPM-ABJ/I/2026 | C13: 46029 | D13: 46028 | E13: BPM | F13: Penagihan Pekerjaan Sambungan Langsung | G13: Konfirmasi pihak ABJ terhadap pengendaan denda terhadap keterlambatan SL | H13: Project | I13: Greenfield | J13: Sambungan Langsung | L13: Open | M13: Level 1 | N13: PMO NC | O13: A. Levi | P13: =DATEDIF(C13,$W$1,"Y")&" tahun, "&DATEDIF(C13,$W$1,"YM")&" bulan, "&DATEDIF(C13,$W$1,"MD")&" hari" -> 0 tahun, 6 bulan, 8 hari | Q13: =DATEDIF(C13,Summary!$A$1,"d") -> 189 | R13: lewat 30d | S13: {=_xlfn.IFS(Q13<=T13,T13,Q13<=T13*2,T13*2,Q13<=T13*3,T13*3,Q13>T13*3,">"&T13*3)} -> >21 | T13: {=_xlfn.IFS(M13="Level 1",7,M13="Level 2",14,M13="Level 3","30",M13="Info","Info",M13="Closed","Closed")} -> 7
A14: 13 | B14: 4722/PS.04.03/EKST/XII/2025 | C14: 46031 | D14: 46022 | E14: PAM JAYA | F14: Tanggapan Pengiriman Dokumen Desain Akhir Program Rehabilitasi Proyek Brownfield Tahun 2026 | G14: PAM JAYA meminta ABJ untuk klarifikasi atas desain akhir maksimal 30 hari kerja sejak dokumen ditanggapi PAM/KPI | H14: Project | I14: Cyclical | J14: Perencanaan Program Greenfield | L14: Closed | M14: Closed | N14: PMO Cyclical | O14: Agus H | P14: =DATEDIF(C14,$W$1,"Y")&" tahun, "&DATEDIF(C14,$W$1,"YM")&" bulan, "&DATEDIF(C14,$W$1,"MD")&" hari" -> 0 tahun, 6 bulan, 6 hari | Q14: =DATEDIF(C14,Summary!$A$1,"d") -> 187 | S14: {=_xlfn.IFS(Q14<=T14,T14,Q14<=T14*2,T14*2,Q14<=T14*3,T14*3,Q14>T14*3,">"&T14*3)} -> Closed | T14: {=_xlfn.IFS(M14="Level 1",7,M14="Level 2",14,M14="Level 3","30",M14="Info","Info",M14="Closed","Closed")} -> Closed | U14: Dibalas Surat ABJ/DIR/EKS/01.26/0076
A15: 14 | B15: e-69888/PP.01.05 | C15: 46031 | D15: 46008 | E15: PAM JAYA | F15: Teguran atas Pelaksanaan Pemenuhan Perizinan Proyek Bundling | G15: PAM JAYA meminta ABJ untuk menyelesaikan pemenuhan kewajiban perizinan keseluruhan project bundling dan menyampaikan progress perizinan setiap kamis pukul 15.00 | H15: Project | I15: Greenfield | J15: Konstruksi Program Greenfield | L15: Info | M15: Info | N15: PMO; Permit | O15: Danny L; Rais S | P15: =DATEDIF(C15,$W$1,"Y")&" tahun, "&DATEDIF(C15,$W$1,"YM")&" bulan, "&DATEDIF(C15,$W$1,"MD")&" hari" -> 0 tahun, 6 bulan, 6 hari | Q15: =DATEDIF(C15,Summary!$A$1,"d") -> 187 | S15: {=_xlfn.IFS(Q15<=T15,T15,Q15<=T15*2,T15*2,Q15<=T15*3,T15*3,Q15>T15*3,">"&T15*3)} -> Info | T15: {=_xlfn.IFS(M15="Level 1",7,M15="Level 2",14,M15="Level 3","30",M15="Info","Info",M15="Closed","Closed")} -> Info
A16: 15 | B16: e-70776/PP.01.04 | C16: 46031 | D16: 46007 | E16: PAM JAYA | F16: Sanksi Denda atas Kegagalan Kinerja Periode Bulan November 2025 | G16: Denda kegagalan kinerja tekanan IPA Pejompongan 1 (11 November 2025) senilai Rp1.030.742 | H16: Produksi | I16: PJP 1 | J16: Denda & Kegagalan | L16: Closed | M16: Closed | N16: Compliance | O16: Indradi | P16: =DATEDIF(C16,$W$1,"Y")&" tahun, "&DATEDIF(C16,$W$1,"YM")&" bulan, "&DATEDIF(C16,$W$1,"MD")&" hari" -> 0 tahun, 6 bulan, 6 hari | Q16: =DATEDIF(C16,Summary!$A$1,"d") -> 187 | S16: {=_xlfn.IFS(Q16<=T16,T16,Q16<=T16*2,T16*2,Q16<=T16*3,T16*3,Q16>T16*3,">"&T16*3)} -> Closed | T16: {=_xlfn.IFS(M16="Level 1",7,M16="Level 2",14,M16="Level 3","30",M16="Info","Info",M16="Closed","Closed")} -> Closed | U16: Dibalas Surat ABJ/DIR/EKS/01.26/0037
A17: 16 | B17: e-70749/PP.00.02 | C17: 46035 | D17: 46024 | E17: PAM JAYA | F17: Pemutakhiran Desain Akhir JDU JDB JDL dan SL Proyek Greenfield Corporate Customer Regional Utara dan Selatan | G17: PAM JAYA meminta ABJ untuk pemutakhiran DED pada lokasi terlampir | H17: Project | I17: Greenfield | J17: Perencanaan Program Greenfield | L17: Open | M17: Level 2 | N17: PMO Infill | O17: Danny L | P17: =DATEDIF(C17,$W$1,"Y")&" tahun, "&DATEDIF(C17,$W$1,"YM")&" bulan, "&DATEDIF(C17,$W$1,"MD")&" hari" -> 0 tahun, 6 bulan, 2 hari | Q17: =DATEDIF(C17,Summary!$A$1,"d") -> 183 | R17: lewat 30d | S17: {=_xlfn.IFS(Q17<=T17,T17,Q17<=T17*2,T17*2,Q17<=T17*3,T17*3,Q17>T17*3,">"&T17*3)} -> >42 | T17: {=_xlfn.IFS(M17="Level 1",7,M17="Level 2",14,M17="Level 3","30",M17="Info","Info",M17="Closed","Closed")} -> 14
A18: 17 | B18: 153/SCI-KPI/I/2026 | C18: 46041 | D18: 46037 | E18: KPI - Sucofindo | F18: Penyampaian Laporan Penyelesaian Uji Komisioning Project Greenfield – SPAM Jatiluhur Hilir 9 Program | G18: Dapat dilanjutkan ke MC100 | H18: Project | I18: Jatiluhur Hilir | J18: Konstruksi Program Greenfield | L18: Info | M18: Info | N18: PMO Infill | O18: Muhrojin | P18: =DATEDIF(C18,$W$1,"Y")&" tahun, "&DATEDIF(C18,$W$1,"YM")&" bulan, "&DATEDIF(C18,$W$1,"MD")&" hari" -> 0 tahun, 5 bulan, 26 hari | Q18: =DATEDIF(C18,Summary!$A$1,"d") -> 177 | S18: {=_xlfn.IFS(Q18<=T18,T18,Q18<=T18*2,T18*2,Q18<=T18*3,T18*3,Q18>T18*3,">"&T18*3)} -> Info | T18: {=_xlfn.IFS(M18="Level 1",7,M18="Level 2",14,M18="Level 3","30",M18="Info","Info",M18="Closed","Closed")} -> Info
A19: 18 | B19: 016/Dir/Ity/I/2026 | C19: 46049 | D19: 46044 | E19: PT Infra Tama Yakti | F19: Surat Peringatan Akibat Kegagalan Perencanaan Oleh Infratama | G19: Penyampaian bahwa kegagalan disebabkan keterbatasan data eksisting | H19: Project | I19: Project | J19: Perencanaan Program Greenfield | L19: Info | M19: Info | N19: PGO | O19: Angelika | P19: =DATEDIF(C19,$W$1,"Y")&" tahun, "&DATEDIF(C19,$W$1,"YM")&" bulan, "&DATEDIF(C19,$W$1,"MD")&" hari" -> 0 tahun, 5 bulan, 18 hari | Q19: =DATEDIF(C19,Summary!$A$1,"d") -> 169 | S19: {=_xlfn.IFS(Q19<=T19,T19,Q19<=T19*2,T19*2,Q19<=T19*3,T19*3,Q19>T19*3,">"&T19*3)} -> Info | T19: {=_xlfn.IFS(M19="Level 1",7,M19="Level 2",14,M19="Level 3","30",M19="Info","Info",M19="Closed","Closed")} -> Info
A20: 19 | B20: 156/SCI-KPI/I/2026 | C20: 46048 | D20: 46014 | E20: KPI - Sucofindo | F20: Tanggapan atas Surat PT Air Bersih Jakarta No. ABJ/DIR/EKS/01.26/0064 Perihal Penyampaian Laporan Penyelesaian Uji Komisioning Project Greenfield – SPAM Jatiluhur Hilir 2 Program | G20: Dapat dilanjutkan ke MC100 | H20: Project | I20: Jatiluhur Hilir | J20: Konstruksi Program Greenfield | L20: Info | M20: Info | N20: PMO Infill | O20: Muhrojin | P20: =DATEDIF(C20,$W$1,"Y")&" tahun, "&DATEDIF(C20,$W$1,"YM")&" bulan, "&DATEDIF(C20,$W$1,"MD")&" hari" -> 0 tahun, 5 bulan, 19 hari | Q20: =DATEDIF(C20,Summary!$A$1,"d") -> 170 | S20: {=_xlfn.IFS(Q20<=T20,T20,Q20<=T20*2,T20*2,Q20<=T20*3,T20*3,Q20>T20*3,">"&T20*3)} -> Info | T20: {=_xlfn.IFS(M20="Level 1",7,M20="Level 2",14,M20="Level 3","30",M20="Info","Info",M20="Closed","Closed")} -> Info
A21: 20 | B21: e-71304/PP.00.02 | C21: 46049 | D21: 46035 | E21: PAM JAYA | F21: Pemutakhiran Desain Akhir JDU JDB JDL dan SL Proyek Greenfield Regional Selatan dan Utara | G21: PAM JAYA meminta ABJ untuk pemutakhiran DED pada lokasi terlampir | H21: Project | I21: Greenfield | J21: Perencanaan Program Greenfield | L21: Open | M21: Level 2 | N21: PMO Infill | O21: Danny L | P21: =DATEDIF(C21,$W$1,"Y")&" tahun, "&DATEDIF(C21,$W$1,"YM")&" bulan, "&DATEDIF(C21,$W$1,"MD")&" hari" -> 0 tahun, 5 bulan, 18 hari | Q21: =DATEDIF(C21,Summary!$A$1,"d") -> 169 | R21: lewat 30d | S21: {=_xlfn.IFS(Q21<=T21,T21,Q21<=T21*2,T21*2,Q21<=T21*3,T21*3,Q21>T21*3,">"&T21*3)} -> >42 | T21: {=_xlfn.IFS(M21="Level 1",7,M21="Level 2",14,M21="Level 3","30",M21="Info","Info",M21="Closed","Closed")} -> 14
A22: 21 | B22: e-71127/PP.00.06 | C22: 46049 | D22: 46030 | E22: PAM JAYA | F22: Permintaan Pemenuhan Perizinan Pekerjaan TOK 5 April 2026 | G22: PAM JAYA meminta ABJ untuk menyelesaikan dan melakukan pemenuhan kewajiban terkait perizinan proyek bundling TOK April 2026 | H22: Project | I22: Greenfield | J22: Konstruksi Program Greenfield | L22: Open | M22: Level 2 | N22: Pernit | O22: Rais A | P22: =DATEDIF(C22,$W$1,"Y")&" tahun, "&DATEDIF(C22,$W$1,"YM")&" bulan, "&DATEDIF(C22,$W$1,"MD")&" hari" -> 0 tahun, 5 bulan, 18 hari | Q22: =DATEDIF(C22,Summary!$A$1,"d") -> 169 | R22: lewat 30d | S22: {=_xlfn.IFS(Q22<=T22,T22,Q22<=T22*2,T22*2,Q22<=T22*3,T22*3,Q22>T22*3,">"&T22*3)} -> >42 | T22: {=_xlfn.IFS(M22="Level 1",7,M22="Level 2",14,M22="Level 3","30",M22="Info","Info",M22="Closed","Closed")} -> 14
A23: 22 | B23: e-71126/PP.01.02 | C23: 46049 | D23: 46022 | E23: PAM JAYA | F23: Teguran Penerapan Aspek Keselamtan dan Kesehatan Kerja (K3) pada Proyek Greenfield dan Brownfield | G23: PAM JAYA meminta ABJ untuk memastikan ABJ melakukan pemeriksaan atas kewajiban implementasi K3 | H23: Project | I23: Project | J23: HSE | L23: Closed | M23: Closed | N23: HSE | O23: Irsan | P23: =DATEDIF(C23,$W$1,"Y")&" tahun, "&DATEDIF(C23,$W$1,"YM")&" bulan, "&DATEDIF(C23,$W$1,"MD")&" hari" -> 0 tahun, 5 bulan, 18 hari | Q23: =DATEDIF(C23,Summary!$A$1,"d") -> 169 | S23: {=_xlfn.IFS(Q23<=T23,T23,Q23<=T23*2,T23*2,Q23<=T23*3,T23*3,Q23>T23*3,">"&T23*3)} -> Closed | T23: {=_xlfn.IFS(M23="Level 1",7,M23="Level 2",14,M23="Level 3","30",M23="Info","Info",M23="Closed","Closed")} -> Closed | U23: Dibalas Surat ABJ26 0140
A24: 23 | B24: e-71125/PP.01.02 | C24: 46049 | D24: 46021 | E24: PAM JAYA | F24: Teguran Keterlambatan Realisasi Pemasangan Sambungan Langsung Bulan Desember 2025 | G24: PAM JAYA meminta ABJ untuk pemenuhan pemasangan SL selambatnya 5 hari kalender | H24: Project | I24: Greenfield | J24: Sambungan Langsung | K24: =C24+5 -> 46054 | L24: Open | M24: Level 1 | N24: PMO NC | O24: A. Levi | P24: =DATEDIF(C24,$W$1,"Y")&" tahun, "&DATEDIF(C24,$W$1,"YM")&" bulan, "&DATEDIF(C24,$W$1,"MD")&" hari" -> 0 tahun, 5 bulan, 18 hari | Q24: =DATEDIF(C24,Summary!$A$1,"d") -> 169 | R24: lewat 30d | S24: {=_xlfn.IFS(Q24<=T24,T24,Q24<=T24*2,T24*2,Q24<=T24*3,T24*3,Q24>T24*3,">"&T24*3)} -> >21 | T24: {=_xlfn.IFS(M24="Level 1",7,M24="Level 2",14,M24="Level 3","30",M24="Info","Info",M24="Closed","Closed")} -> 7
A25: 24 | B25: 300.1.4/61-Kc.PG-Trantib | C25: 46050 | D25: 46034 | E25: Pemkot Bekasi Kecamatan Pondok Gede | F25: Legalitas Perijinan | G25: Perihal legalitas perizinan terkait penampungn/pembuangan tanah di Jl Jatiwaringin | H25: Project | I25: Greenfield | J25: Koordinasi & Sosialisasi | L25: Info | M25: Info | N25: Permit | O25: Rais A | P25: =DATEDIF(C25,$W$1,"Y")&" tahun, "&DATEDIF(C25,$W$1,"YM")&" bulan, "&DATEDIF(C25,$W$1,"MD")&" hari" -> 0 tahun, 5 bulan, 17 hari | Q25: =DATEDIF(C25,Summary!$A$1,"d") -> 168 | S25: {=_xlfn.IFS(Q25<=T25,T25,Q25<=T25*2,T25*2,Q25<=T25*3,T25*3,Q25>T25*3,">"&T25*3)} -> Info | T25: {=_xlfn.IFS(M25="Level 1",7,M25="Level 2",14,M25="Level 3","30",M25="Info","Info",M25="Closed","Closed")} -> Info
A26: 25 | B26: 158/SCI-KPI/I/2026 | C26: 46052 | E26: KPI - Sucofindo | F26: Surat Pengantar Revisi Laporan Bulanan Proyek Bundling SPAM DKI Jakarta - Konsultan Pengawas Independen Periode Desember 2025 | G26: Laporan Bulanan Desember 2025 | H26: Project | I26: Project | J26: Monitoring & Pelaporan | L26: Info | M26: Info | N26: Compliance | O26: Indradi | P26: =DATEDIF(C26,$W$1,"Y")&" tahun, "&DATEDIF(C26,$W$1,"YM")&" bulan, "&DATEDIF(C26,$W$1,"MD")&" hari" -> 0 tahun, 5 bulan, 15 hari | Q26: =DATEDIF(C26,Summary!$A$1,"d") -> 166 | S26: {=_xlfn.IFS(Q26<=T26,T26,Q26<=T26*2,T26*2,Q26<=T26*3,T26*3,Q26>T26*3,">"&T26*3)} -> Info | T26: {=_xlfn.IFS(M26="Level 1",7,M26="Level 2",14,M26="Level 3","30",M26="Info","Info",M26="Closed","Closed")} -> Info
A27: 26 | B27: 173/SCI-KPI/I/2026 | C27: 46052 | D27: 46048 | E27: KPI - Sucofindo | F27: Tanggapan atas Surat PT Air Bersih Jakarta No. ABJ/DIR/EKS/01.26/0070 Tentang Penyampaian Laporan Penyelesaian Uji Komisioning Project Greenfield - SPAM Buaran 3 Hilir Program Anwar Burhanudin | G27: Dapat dilanjutkan ke MC100 | H27: Project | I27: Buaran 3 Hilir | J27: Konstruksi Program Greenfield | L27: Info | M27: Info | N27: PMO Infill | O27: Topan | P27: =DATEDIF(C27,$W$1,"Y")&" tahun, "&DATEDIF(C27,$W$1,"YM")&" bulan, "&DATEDIF(C27,$W$1,"MD")&" hari" -> 0 tahun, 5 bulan, 15 hari | Q27: =DATEDIF(C27,Summary!$A$1,"d") -> 166 | S27: {=_xlfn.IFS(Q27<=T27,T27,Q27<=T27*2,T27*2,Q27<=T27*3,T27*3,Q27>T27*3,">"&T27*3)} -> Info | T27: {=_xlfn.IFS(M27="Level 1",7,M27="Level 2",14,M27="Level 3","30",M27="Info","Info",M27="Closed","Closed")} -> Info
A28: 27 | B28: e-70219/PP.00.02 | C28: 46055 | D28: 46044 | E28: PAM JAYA | F28: Pemutakhiran Desain Akhir JDU JDB JDL dan SL Proyek Greenfield Regional Barat, Selatan, Utara, Pusat | G28: Agar dilakukan survey bersama dan penyelarasan desain akhir | H28: Project | I28: Greenfield | J28: Perencanaan Program Greenfield | L28: Open | M28: Level 2 | N28: PMO Infill | O28: Danny L | P28: =DATEDIF(C28,$W$1,"Y")&" tahun, "&DATEDIF(C28,$W$1,"YM")&" bulan, "&DATEDIF(C28,$W$1,"MD")&" hari" -> 0 tahun, 5 bulan, 13 hari | Q28: =DATEDIF(C28,Summary!$A$1,"d") -> 163 | R28: lewat 30d | S28: {=_xlfn.IFS(Q28<=T28,T28,Q28<=T28*2,T28*2,Q28<=T28*3,T28*3,Q28>T28*3,">"&T28*3)} -> >42 | T28: {=_xlfn.IFS(M28="Level 1",7,M28="Level 2",14,M28="Level 3","30",M28="Info","Info",M28="Closed","Closed")} -> 14
A29: 28 | B29: e-72121/KU.01.15 | C29: 46055 | D29: 46045 | E29: PAM JAYA | F29: Permintaan Penyampaian Laporan Keuangan Audited Tahun 2025 dan Pemenuhan Kewajiban Penyetoran Ekuitas Tahun 2026 | G29: PAM JAYA meminta ABJ untuk melakukan kewajiban penyetoran ekuitas dan menyampaikan laporan keuangan audited 2025 | H29: Corporate | I29: Corporate | J29: Keuangan, Pembayaran, Investasi | L29: Open | M29: Level 2 | N29: Finance | O29: Nurul S | P29: =DATEDIF(C29,$W$1,"Y")&" tahun, "&DATEDIF(C29,$W$1,"YM")&" bulan, "&DATEDIF(C29,$W$1,"MD")&" hari" -> 0 tahun, 5 bulan, 13 hari | Q29: =DATEDIF(C29,Summary!$A$1,"d") -> 163 | R29: lewat 30d | S29: {=_xlfn.IFS(Q29<=T29,T29,Q29<=T29*2,T29*2,Q29<=T29*3,T29*3,Q29>T29*3,">"&T29*3)} -> >42 | T29: {=_xlfn.IFS(M29="Level 1",7,M29="Level 2",14,M29="Level 3","30",M29="Info","Info",M29="Closed","Closed")} -> 14
A30: 29 | B30: e-72122/PP.00.02 | C30: 46055 | D30: 46043 | E30: PAM JAYA | F30: Pembaharuan Informasi Proyek Greenfield JDU JDB JDL dan SL Regional Selatan, Barat, dan Timur | G30: PAM JAYA meminta ABJ untuk menindaklanjuti lokasi rencana sebagaimana surat terlampir | H30: Project | I30: Greenfield | J30: Perencanaan Program Greenfield | L30: Open | M30: Level 2 | N30: PMO Infill | O30: Danny L | P30: =DATEDIF(C30,$W$1,"Y")&" tahun, "&DATEDIF(C30,$W$1,"YM")&" bulan, "&DATEDIF(C30,$W$1,"MD")&" hari" -> 0 tahun, 5 bulan, 13 hari | Q30: =DATEDIF(C30,Summary!$A$1,"d") -> 163 | R30: lewat 30d | S30: {=_xlfn.IFS(Q30<=T30,T30,Q30<=T30*2,T30*2,Q30<=T30*3,T30*3,Q30>T30*3,">"&T30*3)} -> >42 | T30: {=_xlfn.IFS(M30="Level 1",7,M30="Level 2",14,M30="Level 3","30",M30="Info","Info",M30="Closed","Closed")} -> 14
A31: 30 | B31: e-72124/PP.00.02 | C31: 46055 | D31: 46044 | E31: PAM JAYA | F31: Pembaharuan Informasi Proyek Greenfield JDU JDB JDL dan SL Regional Utara | G31: PAM JAYA meminta ABJ untuk menindaklanjuti rencana lokasi sesuai surat terlampir | H31: Project | I31: Greenfield | J31: Perencanaan Program Greenfield | L31: Open | M31: Level 2 | N31: PMO Infill | O31: Danny L | P31: =DATEDIF(C31,$W$1,"Y")&" tahun, "&DATEDIF(C31,$W$1,"YM")&" bulan, "&DATEDIF(C31,$W$1,"MD")&" hari" -> 0 tahun, 5 bulan, 13 hari | Q31: =DATEDIF(C31,Summary!$A$1,"d") -> 163 | R31: lewat 30d | S31: {=_xlfn.IFS(Q31<=T31,T31,Q31<=T31*2,T31*2,Q31<=T31*3,T31*3,Q31>T31*3,">"&T31*3)} -> >42 | T31: {=_xlfn.IFS(M31="Level 1",7,M31="Level 2",14,M31="Level 3","30",M31="Info","Info",M31="Closed","Closed")} -> 14
A32: 31 | B32: e-72125/PP.00.02 | C32: 46055 | D32: 46045 | E32: PAM JAYA | F32: Pemutakhiran Desain Akhir JDU JDB JDL dan SL Proyek Greenfield Warga Muara Baru Gg. Elektro | G32: PAM JAYA meminta ABJ untuk menindaklanjuti lokasi rencana pekerjaan pada surat terlampir | H32: Project | I32: Greenfield | J32: Perencanaan Program Greenfield | L32: Open | M32: Level 2 | N32: PMO Infill | O32: Danny L | P32: =DATEDIF(C32,$W$1,"Y")&" tahun, "&DATEDIF(C32,$W$1,"YM")&" bulan, "&DATEDIF(C32,$W$1,"MD")&" hari" -> 0 tahun, 5 bulan, 13 hari | Q32: =DATEDIF(C32,Summary!$A$1,"d") -> 163 | R32: lewat 30d | S32: {=_xlfn.IFS(Q32<=T32,T32,Q32<=T32*2,T32*2,Q32<=T32*3,T32*3,Q32>T32*3,">"&T32*3)} -> >42 | T32: {=_xlfn.IFS(M32="Level 1",7,M32="Level 2",14,M32="Level 3","30",M32="Info","Info",M32="Closed","Closed")} -> 14
A33: 32 | B33: e-72126/PP.00.02 | C33: 46055 | D33: 46045 | E33: PAM JAYA | F33: Pemutakhiran Desain Akhir JDU JDB JDL dan SL Proyek Greenfield Bank Rakyat Indonesia (Gudang BRI) | G33: PAM JAYA meminta ABJ untuk menindaklanjuti lokasi rencana pada surat terlampir | H33: Project | I33: Greenfield | J33: Perencanaan Program Greenfield | L33: Open | M33: Level 2 | N33: PMO Infill | O33: Danny L | P33: =DATEDIF(C33,$W$1,"Y")&" tahun, "&DATEDIF(C33,$W$1,"YM")&" bulan, "&DATEDIF(C33,$W$1,"MD")&" hari" -> 0 tahun, 5 bulan, 13 hari | Q33: =DATEDIF(C33,Summary!$A$1,"d") -> 163 | R33: lewat 30d | S33: {=_xlfn.IFS(Q33<=T33,T33,Q33<=T33*2,T33*2,Q33<=T33*3,T33*3,Q33>T33*3,">"&T33*3)} -> >42 | T33: {=_xlfn.IFS(M33="Level 1",7,M33="Level 2",14,M33="Level 3","30",M33="Info","Info",M33="Closed","Closed")} -> 14
A34: 33 | B34: e-72203/PP.00.02 | C34: 46055 | D34: 46079 | E34: PAM JAYA | F34: Pemutakhiran Desain Akhir JDU JDB JDL dan SL Proyek Greenfield Perumahan Bumi Karang Indah | G34: PAM JAYA meminta ABJ untuk menindaklanjuti lokasi rencana pada surat terlampir | H34: Project | I34: Greenfield | J34: Perencanaan Program Greenfield | L34: Open | M34: Level 2 | N34: PMO Infill | O34: Danny L | P34: =DATEDIF(C34,$W$1,"Y")&" tahun, "&DATEDIF(C34,$W$1,"YM")&" bulan, "&DATEDIF(C34,$W$1,"MD")&" hari" -> 0 tahun, 5 bulan, 13 hari | Q34: =DATEDIF(C34,Summary!$A$1,"d") -> 163 | R34: lewat 30d | S34: {=_xlfn.IFS(Q34<=T34,T34,Q34<=T34*2,T34*2,Q34<=T34*3,T34*3,Q34>T34*3,">"&T34*3)} -> >42 | T34: {=_xlfn.IFS(M34="Level 1",7,M34="Level 2",14,M34="Level 3","30",M34="Info","Info",M34="Closed","Closed")} -> 14
A35: 34 | B35: e-72204/PP.00.02 | C35: 46055 | D35: 46048 | E35: PAM JAYA | F35: Pemutakhiran Desain Akhir JDU JDB JDL dan SL Proyek Greenfield Jl. Papanggo II Gg Mangga dan Gg Rambutan dan RW 005 Kelurahan Cilandak | G35: PAM JAYA meminta ABJ untuk menindaklanjuti lokasi rencana pada surat terlampir | H35: Project | I35: Greenfield | J35: Perencanaan Program Greenfield | L35: Open | M35: Level 2 | N35: PMO Infill | O35: Danny L | P35: =DATEDIF(C35,$W$1,"Y")&" tahun, "&DATEDIF(C35,$W$1,"YM")&" bulan, "&DATEDIF(C35,$W$1,"MD")&" hari" -> 0 tahun, 5 bulan, 13 hari | Q35: =DATEDIF(C35,Summary!$A$1,"d") -> 163 | R35: lewat 30d | S35: {=_xlfn.IFS(Q35<=T35,T35,Q35<=T35*2,T35*2,Q35<=T35*3,T35*3,Q35>T35*3,">"&T35*3)} -> >42 | T35: {=_xlfn.IFS(M35="Level 1",7,M35="Level 2",14,M35="Level 3","30",M35="Info","Info",M35="Closed","Closed")} -> 14
A36: 35 | B36: e-72146/PP.03.05 | C36: 46055 | D36: 46041 | E36: PAM JAYA | F36: Penyampaian Hasil Inspeksi K3L Terjadwal di IPA Pulogadung Tahun 2025 | G36: ABJ untuk menyampaikan rencana perbaikan selambatnya 14 hari kalender | H36: Produksi | I36: Pulogadung | J36: HSE | L36: Closed | M36: Closed | N36: HSE | O36: Irsan | P36: =DATEDIF(C36,$W$1,"Y")&" tahun, "&DATEDIF(C36,$W$1,"YM")&" bulan, "&DATEDIF(C36,$W$1,"MD")&" hari" -> 0 tahun, 5 bulan, 13 hari | Q36: =DATEDIF(C36,Summary!$A$1,"d") -> 163 | S36: {=_xlfn.IFS(Q36<=T36,T36,Q36<=T36*2,T36*2,Q36<=T36*3,T36*3,Q36>T36*3,">"&T36*3)} -> Closed | T36: {=_xlfn.IFS(M36="Level 1",7,M36="Level 2",14,M36="Level 3","30",M36="Info","Info",M36="Closed","Closed")} -> Closed | U36: Dibalas Surat ABJ26 0106
