Workbook

Sheet Dashboard

Sheet Summary
A1: =TODAY() -> 46304
M2: Monitoring Surat 2026
A3: Keterangan | M3: Keterangan | N3: Compliance | O3: Corcom | P3: Finance | Q3: HC | R3: HSE | V3: Maintenance | W3: Permit | X3: Planning | Y3: PMO | Z3: Produksi | AA3: SCM | AB3: QMS | AC3: WQA
A4: Level 1 | B4: Perlu dibalas dengan tenggat waktu (max 7 hari) | M4: Incoming Open | N4: =COUNTIFS('Incoming 2026'!L:L,$B$19,'Incoming 2026'!R:R,N3) -> 1 | O4: =COUNTIFS('Incoming 2026'!L:L,$B$19,'Incoming 2026'!R:R,"$O$3") -> 0 | P4: =COUNTIFS('Incoming 2026'!L:L,$B$19,'Incoming 2026'!R:R,"HC") -> 0 | Q4: =COUNTIFS('Incoming 2026'!L:L,$B$19,'Incoming 2026'!R:R,"HC") -> 0 | R4: =COUNTIFS('Incoming 2026'!L:L,$B$19,'Incoming 2026'!R:R,"HSE") -> 13 | V4: =COUNTIFS('Incoming 2026'!L:L,$B$19,'Incoming 2026'!R:R,"maintenance") -> 0 | W4: =COUNTIFS('Incoming 2026'!L:L,$B$19,'Incoming 2026'!R:R,"permit") -> 7 | X4: =COUNTIFS('Incoming 2026'!L:L,$B$19,'Incoming 2026'!R:R,"Planning") -> 19 | Y4: =COUNTIFS('Incoming 2026'!L:L,$B$19,'Incoming 2026'!R:R,"PMO") -> 2 | Z4: =COUNTIFS('Incoming 2026'!L:L,$B$19,'Incoming 2026'!R:R,"Produksi") -> 0 | AA4: =COUNTIFS('Incoming 2024'!L:L,$B$19,'Incoming 2024'!N:N,"SCM") -> 0 | AB4: =COUNTIFS('Incoming 2024'!L:L,$B$19,'Incoming 2024'!N:N,"QMS") -> 0 | AC4: =COUNTIFS('Incoming 2024'!L:L,$B$19,'Incoming 2024'!N:N,"WQA") -> 0
A5: Level 2 | B5: Perlu dibalas dengan tenggat waktu (Max 14 hari) | M5: Incoming Closed | N5: =COUNTIFS('Incoming 2026'!L:L,Summary!$B$20,'Incoming 2026'!R:R,Summary!N3) -> 21 | O5: =COUNTIFS('Incoming 2026'!L:L,Summary!$B$20,'Incoming 2026'!R:R,Summary!O3) -> 0 | P5: =COUNTIFS('Incoming 2026'!L:L,Summary!$B$20,'Incoming 2026'!R:R,Summary!P3) -> 7 | Q5: =COUNTIFS('Incoming 2026'!L:L,Summary!$B$20,'Incoming 2026'!R:R,Summary!Q3) -> 1 | R5: =COUNTIFS('Incoming 2026'!L:L,Summary!$B$20,'Incoming 2026'!R:R,Summary!R3) -> 121 | V5: =COUNTIFS('Incoming 2026'!L:L,Summary!$B$20,'Incoming 2026'!R:R,Summary!V3) -> 0 | W5: =COUNTIFS('Incoming 2026'!L:L,Summary!$B$20,'Incoming 2026'!R:R,Summary!W3) -> 4 | X5: =COUNTIFS('Incoming 2026'!L:L,Summary!$B$20,'Incoming 2026'!R:R,Summary!X3) -> 15 | Y5: =COUNTIFS('Incoming 2026'!L:L,Summary!$B$20,'Incoming 2026'!R:R,Summary!Y3) -> 0 | Z5: =COUNTIFS('Incoming 2026'!L:L,Summary!$B$20,'Incoming 2026'!R:R,Summary!Z3) -> 13 | AA5: =COUNTIFS('Incoming 2024'!L:L,Summary!$B$20,'Incoming 2024'!N:N,Summary!AA3) -> 0 | AB5: =COUNTIFS('Incoming 2024'!L:L,Summary!$B$20,'Incoming 2024'!N:N,Summary!AB3) -> 1 | AC5: =COUNTIFS('Incoming 2024'!L:L,Summary!$B$20,'Incoming 2024'!N:N,Summary!AC3) -> 2
A6: Level 3 | B6: Perlu dibalas dengan tenggat waktu (Max 30 hari) | M6: Outgoing Open | N6: =COUNTIFS('Outgoing 2026'!L:L,$B$19,'Outgoing 2026'!M:M,"compliance") -> 17 | O6: =COUNTIFS('Outgoing 2026'!L:L,$B$19,'Outgoing 2026'!M:M,"corcom") -> 0 | P6: =COUNTIFS('Outgoing 2026'!L:L,$B$19,'Outgoing 2026'!M:M,"Finance") -> 2 | Q6: =COUNTIFS('Outgoing 2026'!L:L,$B$19,'Outgoing 2026'!M:M,"HC") -> 0 | R6: =COUNTIFS('Outgoing 2026'!L:L,$B$19,'Outgoing 2026'!M:M,"HSE") -> 2 | V6: =COUNTIFS('Outgoing 2026'!L:L,$B$19,'Outgoing 2026'!M:M,"Maintenance") -> 0 | W6: =COUNTIFS('Outgoing 2026'!L:L,$B$19,'Outgoing 2026'!M:M,"Permit") -> 6 | X6: =COUNTIFS('Outgoing 2026'!L:L,$B$19,'Outgoing 2026'!M:M,"Planning") -> 6 | Y6: =COUNTIFS('Outgoing 2026'!L:L,$B$19,'Outgoing 2026'!M:M,$Y$3) -> 0 | Z6: =COUNTIFS('Outgoing 2026'!L:L,$B$19,'Outgoing 2026'!M:M,$Z$3) -> 3 | AA6: =COUNTIFS('Outgoing 2024'!K:K,$B$19,'Outgoing 2024'!L:L,$AA$3) -> 0 | AB6: =COUNTIFS('Outgoing 2024'!K:K,$B$19,'Outgoing 2024'!L:L,$AB$3) -> 0 | AC6: =COUNTIFS('Outgoing 2024'!K:K,$B$19,'Outgoing 2024'!L:L,$AC$3) -> 0
M7: Outgoing Closed | N7: =COUNTIFS('Outgoing 2026'!L:L,$B$20,'Outgoing 2026'!M:M,"compliance") -> 24 | O7: =COUNTIFS('Outgoing 2026'!L:L,$B$20,'Outgoing 2026'!M:M,"corcom") -> 0 | P7: =COUNTIFS('Outgoing 2026'!L:L,$B$20,'Outgoing 2026'!M:M,"Finance") -> 0 | Q7: =COUNTIFS('Outgoing 2026'!L:L,$B$20,'Outgoing 2026'!M:M,"HC") -> 0 | R7: =COUNTIFS('Outgoing 2026'!L:L,$B$20,'Outgoing 2026'!M:M,"HSE") -> 0 | V7: =COUNTIFS('Outgoing 2026'!L:L,$B$20,'Outgoing 2026'!M:M,"Maintenance") -> 0 | W7: =COUNTIFS('Outgoing 2026'!L:L,$B$20,'Outgoing 2026'!M:M,"Permit") -> 0 | X7: =COUNTIFS('Outgoing 2026'!L:L,$B$20,'Outgoing 2026'!M:M,"Planning") -> 2 | Y7: =COUNTIFS('Outgoing 2026'!L:L,$B$20,'Outgoing 2026'!M:M,$Y$3) -> 0 | Z7: =COUNTIFS('Outgoing 2026'!L:L,$B$20,'Outgoing 2026'!M:M,$Z$3) -> 0 | AA7: =COUNTIFS('Outgoing 2024'!K:K,$B$20,'Outgoing 2024'!L:L,$AA$3) -> 0 | AB7: =COUNTIFS('Outgoing 2024'!K:K,$B$20,'Outgoing 2024'!L:L,$AB$3) -> 0 | AC7: =COUNTIFS('Outgoing 2024'!K:K,$B$20,'Outgoing 2024'!L:L,$AC$3) -> 1
A8: 1) Total Surat | B8: 2023 | C8: Incoming | D8: =SUBTOTAL(3,'Incoming 2023'!D:D) -> 439
C9: Outgoing | D9: =SUBTOTAL(3,'Outgoing 2023'!B:B) -> 531
B10: 2024 | C10: Incoming | D10: =SUBTOTAL(3,'Incoming 2024'!B:B) -> 2
C11: Outgoing | D11: =SUBTOTAL(3,'Outgoing 2024'!A:A) -> 975
B12: 2025 | C12: Incoming | D12: =SUBTOTAL(3,'Incoming 2025'!B2:B2001) -> 502
C13: Outgoing | D13: =SUBTOTAL(3,'Outgoing 2025'!B2:B1898) -> 1158
B14: 2026 | C14: Incoming | D14: =SUBTOTAL(3,'Incoming 2026'!B2:B1984) -> 558
C15: Outgoing | D15: =SUBTOTAL(3,'Outgoing 2026'!B2:B1500) -> 1298
B18: Surat Masuk | C18: 2026 | D18: 2025 | E18: 2024 | F18: 2023 | I18: Surat Keluar | J18: 2026 | K18: 2025 | L18: 2024
B19: Open | C19: =COUNTIF('Incoming 2026'!L2:L1982,Summary!B19) -> 78 | D19: =COUNTIF('Incoming 2025'!L2:L2001,Summary!B19) -> 39 | E19: =COUNTIF('Incoming 2024'!L:L,"open") -> 37 | F19: =COUNTIF('Incoming 2023'!I:I,"open") -> 9 | I19: Open | J19: =COUNTIF('Outgoing 2026'!$L$2:$L$952,Summary!I19) -> 38 | K19: =COUNTIF('Outgoing 2025'!K2:K963,Summary!I19) -> 11 | L19: =COUNTIF('Outgoing 2024'!K:K,"Open") -> 2
B20: Closed | C20: =COUNTIF('Incoming 2026'!L2:L1982,Summary!B20) -> 247 | D20: =COUNTIF('Incoming 2025'!L3:L2001,Summary!B20) -> 116 | E20: =COUNTIF('Incoming 2024'!L:L,"closed") -> 244 | F20: =COUNTIF('Incoming 2023'!I:I,"closed") -> 252 | I20: Closed | J20: =COUNTIF('Outgoing 2026'!$L$2:$L$952,Summary!I20) -> 35 | K20: =COUNTIF('Outgoing 2025'!K3:K963,Summary!I20) -> 7 | L20: =COUNTIF('Outgoing 2024'!K:K,"Closed") -> 177
B21: Info | C21: =COUNTIF('Incoming 2026'!L2:L1983,Summary!B21) -> 233 | D21: =COUNTIF('Incoming 2025'!L4:L1001,Summary!B21) -> 338 | E21: =COUNTIF('Incoming 2024'!L:L,"info") -> 553 | F21: =COUNTIF('Incoming 2023'!I:I,"info") -> 177 | I21: Info | J21: =COUNTIF('Outgoing 2026'!$L$2:$L$952,Summary!I21) -> 877 | K21: =COUNTIF('Outgoing 2025'!K4:K963,Summary!I21) -> 639 | L21: =COUNTIF('Outgoing 2024'!K:K,"Info") -> 777
M34: Jumlah surat masuk berdasarkan Durasi Keterlambatan
N35: 7 | O35: 14 | P35: 21 | Q35: 30
M36: Level 1 | N36: =COUNTIF('Incoming 2026'!M2:M191,Summary!M36) -> 10 | O36: =COUNTIFS('Incoming 2026'!M:M,Summary!M36,'Incoming 2026'!W:W,Summary!O35) -> 0 | P36: =COUNTIFS('Incoming 2026'!M:M,Summary!M36,'Incoming 2026'!W:W,Summary!P35) -> 0 | Q36: =COUNTIFS('Incoming 2026'!M:M,Summary!N36,'Incoming 2026'!W:W,Summary!Q35) -> 0
M37: Level 2 | N37: =COUNTIF('Incoming 2026'!M3:M192,Summary!M37) -> 20 | O37: =COUNTIFS('Incoming 2026'!M:M,Summary!M37,'Incoming 2026'!W:W,Summary!O35) -> 0 | P37: =COUNTIFS('Incoming 2026'!M:M,Summary!M37,'Incoming 2026'!W:W,Summary!P35) -> 0 | Q37: =COUNTIFS('Incoming 2026'!M:M,Summary!M37,'Incoming 2026'!W:W,Summary!Q35) -> 0
M38: Level 3 | N38: =COUNTIF('Incoming 2026'!M4:M193,Summary!M38) -> 2 | O38: =COUNTIFS('Incoming 2026'!M:M,Summary!M38,'Incoming 2026'!W:W,Summary!O35) -> 0 | P38: =COUNTIFS('Incoming 2026'!M:M,Summary!M38,'Incoming 2026'!W:W,Summary!P35) -> 0 | Q38: =COUNTIFS('Incoming 2026'!M:M,Summary!M38,'Incoming 2026'!W:W,Summary!Q35) -> 2
A40: Kategori Surat
A41: TOK | B41: =COUNTIF('Incoming 2026'!#REF!,A41) -> #REF!
A42: DED/RAB | B42: =COUNTIF('Incoming 2026'!#REF!,A42) -> #REF!
A43: PKS | B43: =COUNTIF('Incoming 2026'!#REF!,A43) -> #REF!
A44: Dokumentasi | B44: =COUNTIF('Incoming 2026'!#REF!,A44) -> #REF!
A45: Denda | B45: =COUNTIF('Incoming 2026'!#REF!,A45) -> #REF!
A46: Perizinan | B46: =COUNTIF('Incoming 2026'!#REF!,A46) -> #REF!
A47: Sambungan Rumah/Sambungan Baru | B47: =COUNTIF('Incoming 2026'!#REF!,A47) -> #REF!
A48: Teguran | B48: =COUNTIF('Incoming 2026'!#REF!,A48) -> #REF!
A49: Komisioning/Pengoperasian | B49: =COUNTIF('Incoming 2026'!#REF!,A49) -> #REF!
A50: Spesifikasi Teknis/Metode Kerja | B50: =COUNTIF('Incoming 2026'!#REF!,A50) -> #REF!
A51: Inspeksi | B51: =COUNTIF('Incoming 2026'!#REF!,A51) -> #REF!
A53: Pengadaan | B53: =COUNTIF('Incoming 2026'!#REF!,A53) -> #REF!
... A56: Rencana Pekerjaan | B56: =COUNTIF('Incoming 2026'!#REF!,A56) -> #REF!
A59: Kategori Surat Masuk "Open"
A60: Shop Drawing | B60: =COUNTIFS('Incoming 2025'!L:L,Summary!$B$19,'Incoming 2025'!J:J,Summary!A60) -> 0
...

Sheet Reminder
A1: Reminder Surat Masuk
A2: No | B2: Nomor Surat | C2: Perihal | D2: Keterangan | E2: PIC | F2: Due Date | G2: Status
A3: 1 | B3: e-80724/PP.01.02 | C3: Teguran atas Ketidaksesuaian Pelaksanaan Pengurugan dan Perbaikan Bekas Galian yang Berdampak pada Gangguan Lalu Lintas dan Keterlambatan Penyelesaian Proyek pada Program Infill SPAM Buaran III | D3: PAM JAYA menemukan 168 titik bekas galian yang belum diperbaiki sesuai standar, penerapan K3 yang belum memadai, gangguan lalu lintas, serta pekerjaan yang menimbulkan keluhan masyarakat dan pemberitaan negatif pada PAMJAYA (wilayah condet) | ABJ diminta untuk segera perbaikin hal tersebut | E3: PMO Infill - Topan | F3: 46224 | G3: =_xlfn.XLOOKUP(B3,'Incoming 2026'!$B$2:$B$531,'Incoming 2026'!$L$2:$L$531) -> Open
A4: 2 | B4: e-81788/PP.01.05 | C4: Permintaan Klarifikasi Pelaksanaan Pekerjaan IBP Basura | D4: PAM JAYA mempertanyakan dan meminta justifikasi teknis yang lengkap atas perubahan desain pompa pada proyek IBP Basura dari pompa sentrifugal menjadi pompa submersible, karena perubahan tersebut dinilai belum didukung penjelasan dan dokumen yang memadai. | E4: PMO Infill-Yodi | F4: 46224 | G4: =_xlfn.XLOOKUP(B4,'Incoming 2026'!$B$2:$B$531,'Incoming 2026'!$L$2:$L$531) -> Open
A5: 3 | B5: 2633/PS.04.04/EKST/VI/2026 | C5: Teguran Pemenuhan Kewajiban Penyelesaian Paket Pekerjaaan Ketiga Proyek Greenfield Pada Saat Tanggal Operasi Komersial atau 5 April 2026 | D5: PAM JAYA menegaskan bahwa dari 108 pekerjaan hanya 91 yang diakui selesai, masih terdapat 42 pekerjaan yang belum selesai, dan meminta PT ABJ segera menuntaskan seluruh pekerjaan beserta pemenuhan dokumen, kualitas, dan pelaporan progres. | E5: PMO Infill-Suci | F5: 46224 | G5: =_xlfn.XLOOKUP(B5,'Incoming 2026'!$B$2:$B$531,'Incoming 2026'!$L$2:$L$531) -> Open
A6: 4 | B6: E-73652/PP.01.05 | C6: Teguran atas Bina Marga Nomor 266/KR.02.00 perihal Pelaksanaan Pekerjaan Galian Utilitas Pipa Air Bersih | D6: Teguran atas Bina Marga Nomor 266/KR.02.00 perihal Pelaksanaan Pekerjaan Galian Utilitas Pipa Air Bersih | E6: PMO Infill; PMO TM-Suci; Jusman | F6: 46224 | G6: =_xlfn.XLOOKUP(B6,'Incoming 2026'!$B$2:$B$531,'Incoming 2026'!$L$2:$L$531) -> Open
A7: 5 | B7: e-76093/PP.01.02 | C7: Teguran atas Pengawasan Aspek Keselamatan dan Kesehatan Kerja (K3) pada Proyek Bundling | D7: PAM JAYA menilai pengawasan K3 oleh KPI belum optimal dan meminta KPI memperketat pengawasan serta memastikan kepatuhan K3 pada seluruh proyek bundling. | E7: HSE-Irsan | F7: 46224 | G7: =_xlfn.XLOOKUP(B7,'Incoming 2026'!$B$2:$B$531,'Incoming 2026'!$L$2:$L$531) -> Open
A8: 6 | B8: e-75059/PP.01.05 | C8: Permintaan Penjelasan dan Klarifikasi atas permasalahan pada Proyek SPAM Buaran Hulu di RW 03 Kelurahan Margahayu Kecamatan Bekasi Timur Kota Bekasi | D8: ABJ diminta menyelesaikan permasalahan, perizinan, dan koordinasi proyek SPAM Buaran Hulu serta memastikan kepatuhan terhadap ketentuan yang berlaku. | E8: PMO B3 Hulu - A. Yudi | F8: 46224 | G8: =_xlfn.XLOOKUP(B8,'Incoming 2026'!$B$2:$B$531,'Incoming 2026'!$L$2:$L$531) -> Open
A9: 7 | B9: e-76341/PP.01.02 | C9: Teguran atas Ketidak-sesuaian Pelaksanaan Pengurugan dan Perbaikan Bekas Galian yang Berdampak pada Gangguan Lalu Lintas, Keterlambatan Penyelesaian Proyek, serta Kewajiban Penggantian Kompensasi Pohon Terdampak Pekerjaan Pemasangan Pipa pada Program Infill SPAM Buaran III | D9: PT ABJ dinilai belum optimal dalam pelaksanaan pekerjaan, mitigasi lalu lintas, K3, dan perizinan. PAM JAYA menegur dan meminta PT ABJ untuk segera menindaklanjuti perbaikan 98 temuan, mengganti pohon terdampak, mempercepat penyelesaian proyek, meningkatkan keselamatan kerja | E9: PMO Infill - Topan | F9: 46224 | G9: =_xlfn.XLOOKUP(B9,'Incoming 2026'!$B$2:$B$531,'Incoming 2026'!$L$2:$L$531) -> Open
A10: 8 | B10: e-76737/PP.01.02 | C10: Teguran atas Kelalaian PT ABJ atas Pelaksanaan Pekerjaan Yang Tidak Sesuai dengan Praktik Industri Yang Baik pada di Jalan Raya Taman Mini pada Proyek Buaran Hilir | D10: ABJ dinilai lalai dalam proyek Buaran Hilir menyebabkan banjir dan gangguan lalu lintas, Penyebab: tidak sesuai prosedur, kurang pengecekan, dan lambat penanganan. Pelanggaran akan ditindaklanjuti sesuai perjanjian. | E10: PMO Infill-Topan | F10: 46224 | G10: =_xlfn.XLOOKUP(B10,'Incoming 2026'!$B$2:$B$531,'Incoming 2026'!$L$2:$L$531) -> Open
A11: 9 | B11: e-80737/PS.04.06 | C11: Pembangunan Sistem Hilir IPA Condet dan Sistem Hilir IPA Semanan | D11: ABJ diminta menyampaikan usulan program konstruksi untuk sistem hilir IPA Semanan dan IPA Condet dan memberikan rekomendasi pemodelan hidrolis jaringan dan skenario desain jaringan pipa yang terintegrasi | E11: Planning - Aji S | F11: 46224 | G11: =_xlfn.XLOOKUP(B11,'Incoming 2026'!$B$2:$B$531,'Incoming 2026'!$L$2:$L$531) -> Open
A12: 10 | B12: 328/SCI-KPI/VII/2026 | C12: Permohonan Informasi Terkait Insiden Kecelakaan Kerja Lokasi Chamber P6 STA 2+200 Jalan Raya Mabes Hankam – Buaran 3 Hilir | D12: ABJ diminta menyampaikan informasi lengkap terkait insiden fatality, hasil investigasi, kepatuhan K3, dan rencana tindak lanjut. | E12: HSE - Suhendro PMO TM - Jusman | F12: 46241 | G12: =_xlfn.XLOOKUP(B12,'Incoming 2026'!$B$2:$B$531,'Incoming 2026'!$L$2:$L$531) -> Open
A13: 11 | B13: 2448/PS.04.02/EKST/VI/2026 | C13: Tindak Lanjut Pemenuhan Kewajiban Asuransi Berdasarkan A&PK Bundling | D13: ABJ diminta untuk menyampaikan seluruh dokumen dan melakukan perbaikan sebagaimana dimaksud dalam surat ini paling lambat 7 hari setelah surat ini diterima | E13: PMO Infill - Suci PMO TM - Jusman | F13: 46241 | G13: =_xlfn.XLOOKUP(B13,'Incoming 2026'!$B$2:$B$531,'Incoming 2026'!$L$2:$L$531) -> Open
A14: 12 | B14: e-84089/PP.01.05 | C14: Permintaan Kepatuhan Terkait Tahapan Pekerjaan Konstruksi Pada Proyek Greenfield | D14: ABJ diminta berkomitmen melaksanakan pekerjaan konstruksi Fasilitas Baru sesuai ketentuan Perjanjian Kerja Sama Bundling dan peraturan yang berlaku, serta menegaskan bahwa setiap pelanggaran akan ditindaklanjuti sesuai ketentuan perjanjian. | E14: PMO Infill - Suci PMO TM - Jusman | F14: 46241 | G14: =_xlfn.XLOOKUP(B14,'Incoming 2026'!$B$2:$B$531,'Incoming 2026'!$L$2:$L$531) -> Open
... A26: 24 | B26: 4407/KU.01.08/EKST/IX/2026 | C26: Permohonan Pembayaran atas Pemanfaatan Lahan milik PPPK Kemayoran untuk Pembangunan Reservoir Kebon Kosong Project SPAM Jatiluhur Hilir | D26: PAM JAYA meminta ABJ untuk: (a) Melakukan pembayaran atas pemanfaatan lahan sesuai Amandemen & Perjanjian Kerja Sama Bundling, paling lambat 29 September 2026. (b) Menyampaikan bukti pembayaran ke PAM JAYA maksimal 3 hari setelah pembayaran dilakukan. (c) Memastikan pemenuhan perizinan agar pelaksanaan proyek tidak terlambat/terganggu (kewajiban ABJ). | E26: Permit - Rudy | F26: 46296 | G26: =_xlfn.XLOOKUP(B26,'Incoming 2026'!$B$2:$B$531,'Incoming 2026'!$L$2:$L$531) -> Open
A27: 25 | B27: 4398/PS.04.01/EKST/IX/2026 | C27: Permintaan Tindak Lanjut Pembangunan Jaringan Pipa Pendukung Sistem DC Semanan SPAM Karian Serpong Hilir | E27: PMO Infill - Ervin | F27: 46296 | G27: =_xlfn.XLOOKUP(B27,'Incoming 2026'!$B$2:$B$531,'Incoming 2026'!$L$2:$L$531) -> Open
A28: 26 | B28: 4521/PS.04.04/EKST/IX/2026 | C28: Teguran Penerapan Aspek Keselamatan dan Kesehatan Kerja ("K3") Proyek Greenfield Jatiluhur Hilir | D28: Inspeksi K3 15 Sep 2026. Temuan: pit galian tidak memperhatikan aspek lingkungan; proteksi galian tidak standar; kerapian area; rambu belum lengkap; flagman tidak memadai (1 personel); pekerja tanpa APD; pengawasan kontraktor tidak berkala; bekas galian belum dirapikan. | E28: HSE - Suhendro | F28: 46296 | G28: =_xlfn.XLOOKUP(B28,'Incoming 2026'!$B$2:$B$531,'Incoming 2026'!$L$2:$L$531) -> Open
A29: 27 | B29: 4520/PS.04.04/EKST/IX/2026 | C29: Teguran Penerapan Aspek Keselamatan dan Kesehatan Kerja ("K3") Proyek Jatiluhur Hilir Infil Paket 070 Rorotan 9, Malaka 1,2,3 & Rorotan 11 dan 077 | D29: Inspeksi K3 15 Sep 2026. Temuan: stiker belum sesuai kesepakatan; housekeeping tanah galian; pengaman galian tidak sesuai standar PAM JAYA; rambu belum lengkap; tidak ada flagman. | E29: HSE - Suhendro | F29: 46296 | G29: =_xlfn.XLOOKUP(B29,'Incoming 2026'!$B$2:$B$531,'Incoming 2026'!$L$2:$L$531) -> Open
A30: 28 | B30: 4532/PS.04.04/EKST/IX/2026 | C30: Teguran atas pelaksanaan pemenuhan perizinan proyek bundling TOK 5 Oktober 2026 | D30: Hasil monitoring dashboard 3 Sep 2026: IPPJU 97 terbit, 5 upload Jakevo, 3 tidak perlu; Crossing Sungai BBWS Cilcis: 1 pemenuhan data, 2 tunggu survei, 5 proses rekomtek, 1 terbit; Crossing Kali Jakarta (SDA DKI): 2 tunggu survei UP4, 4 proses SSRD, 35 proses rekomtek, 12 rekomtek terbit; Crossing Tol 2 terbit; Crossing Rel KA 2 terbit. | E30: Permit - Rudy | F30: 46296 | G30: =_xlfn.XLOOKUP(B30,'Incoming 2026'!$B$2:$B$531,'Incoming 2026'!$L$2:$L$531) -> Open
A31: 29 | B31: 4523/PS.04.04/EKST/IX/2026 | C31: Teguran Keras Penerapan Aspek Keselamatan dan Kesehatan Kerja ("K3") Proyek Greenfield Jatiluhur Hilir | D31: Inspeksi K3 11–12 Sep 2026. Temuan: proteksi galian belum standar; kerapian area; rambu belum lengkap; insiden kendaraan amblas di area kerja akibat ketidakpatuhan K3. | E31: HSE - Suhendro | F31: 46296 | G31: =_xlfn.XLOOKUP(B31,'Incoming 2026'!$B$2:$B$531,'Incoming 2026'!$L$2:$L$531) -> Open
A32: 30 | B32: 4647/PS.04.01/EKST/IX/2026 | C32: Permintaan Kelengkapan Dokumen atas Permohonan Sewa Infrastruktur pada Satuan Kerja BBWS Pekerjaan Jenderal Citarum Umum Sumber Kementerian Direktorat Daya Air | D32: Menindaklanjuti Surat Kementerian PU PS0301-AV/964 (20 Okt 2025) atas usulan sewa BMN (tanah untuk jalan nasional) untuk intake Buaran 3 Hulu. PAM JAYA diminta melengkapi: usulan faktor penyesuai sewa (dgn pertimbangan instansi teknis), proposal/studi kelayakan (rencana usaha, operasional, keuangan, desain & layout bangunan), dan surat rekomendasi kelayakan dari instansi teknis. | E32: PMO B3 Hulu - A. Yudi | F32: 46296 | G32: =_xlfn.XLOOKUP(B32,'Incoming 2026'!$B$2:$B$531,'Incoming 2026'!$L$2:$L$531) -> Open
A33: 31 | B33: 4621/PS.04.04/EKST/IX/2026 | C33: Teguran Penerapan Aspek Keselamatan dan Kesehatan Kerja ("K3") Proyek Greenfield Jatiluhur Hilir | D33: Inspeksi K3 15 Sep 2026. Temuan: pit galian tidak memperhatikan aspek lingkungan; proteksi galian tidak standar; kerapian area; rambu belum lengkap; flagman tidak memadai (1 personel); pekerja tanpa APD; pengawasan kontraktor tidak berkala; bekas galian belum dirapikan. | E33: HSE - Suhendro | F33: 46296 | G33: =_xlfn.XLOOKUP(B33,'Incoming 2026'!$B$2:$B$531,'Incoming 2026'!$L$2:$L$531) -> Open
A34: 32 | B34: 4622/PS.04.04/EKST/IX/2026 | C34: Teguran Penerapan Aspek Keselamatan dan Kesehatan Kerja ("K3") Proyek Jatiluhur Hilir | D34: Temuan inspeksi K3 tanggal 16 September 2026. Temuan : Pagar Proyek Daur Ulang (PPDU) belum sesuai standar PAM JAYA; APD; Galian; Rambu K3; Papan informasi proyek belum ada | E34: HSE - Suhendro | F34: 46296 | G34: =_xlfn.XLOOKUP(B34,'Incoming 2026'!$B$2:$B$531,'Incoming 2026'!$L$2:$L$531) -> Open
A35: 33 | B35: 3821/PS.04.01/EKSI/VIII/2026 | C35: Permintaan Pembaharuan Program Konstruksi | D35: Suplai air curah SPAM Karian-Serpong (jadwal Lampiran 24 A&R Greenfield: April 2027) terlambat menurut Surat PUPR 751, belum ada kepastian. Mengacu Pergub 48/2025 & Rencana Bisnis PAM JAYA 2025–2029, PAM JAYA menargetkan IPA baru: IPA Semanan 200 lps, IPA Condet 1.000 lps, IPA Polor 1.500 lps. (Menjawab Surat ABJ 0821 tgl 7 Okt 2025 yg meminta arahan program konstruksi terkait suplai Karian-Serpong.) | E35: Planning - Aji S | F35: 46296 | G35: =_xlfn.XLOOKUP(B35,'Incoming 2026'!$B$2:$B$531,'Incoming 2026'!$L$2:$L$531) -> Info
A36: 34 | B36: 4690/PS.04.04/EKSI/IX/2026 | C36: Surat Teguran atas Kelalaian PT ABJ atas Pelaksanaan Pekerjaan Yang Tidak Sesuai dengan Praktik Industri Yang Baik pada di Jalan Elang dan Jalan Merpati pada Proyek Buaran III Hilir | D36: teguran atas insiden banjir/genangan akibat pekerjaan interkoneksi JDU–JDB–JDL dan meminta ABJ melakukan investigasi akar masalah, menyusun serta melaksanakan tindakan perbaikan dan pencegahan, melakukan pengecekan sarana secara berkala, meningkatkan kehati-hatian dan respons terhadap insiden, memastikan kejadian tidak terulang, serta menyampaikan dokumentasi sebelum dan sesudah perbaikan. | E36: PMO Infill - Topan
A37: 35 | B37: 4689/PS.04.04/EKSI/IX/2026 | C37: Teguran Pelaksanaan Pekerjaan Pemasangan Pipa Yang Tidak Sesuai Standar pada Trunkmain P7 dan S5 SPAM Buaran III Hilir | D37: teguran atas pelaksanaan pekerjaan pemasangan pipa Trunkmain P7 dan S5 yang mengubah metode menjadi open cut tanpa menyampaikan Justifikasi Teknis dan Finansial terlebih dahulu, serta meminta ABJ menghentikan sementara pekerjaan DN 800 open cut, melakukan evaluasi internal, menyampaikan corrective & preventive action, dan memastikan setiap perubahan pekerjaan mendapat justifikasi serta persetujuan sesuai ketentuan PKS Bundling | E37: PMO TM - Jusman
A38: 36 | B38: 4080/PS.04.01/EKST/VIII/2026 | C38: Permintaan Klarifikasi terhadap Perbedaan Ukuran Material Pada Program Rehabilitasi 46331 | D38: ABJ diminta mengklarifikasi perbedaan ukuran material antara desain MC-0 dan kondisi aktual pada Program Rehabilitasi 46331, serta melengkapi dokumen factory, metode handling, justifikasi teknis dan finansial, perhitungan dalam BIM, serta memastikan proses quality control dan pemeriksaan material on-site sesuai ketentuan | E38: PMO Cyclical - Agus H
A39: 37 | B39: 4551/PS.04.01/EKST/IX/2026 | C39: 1(satu) Berkas Permintaan Tindak Lanjut atas Surat PAM JAYA Nomor: 4167/PP.01.02/EKST/IX/2026 Tanggal 2 September 2026 dan Permintaan Rencana Pemenuhan Kewajiban Knowledge Transfer Tanggal Operasi Komersial Fasilitas Distribusi Baru Paket Pekerjaan Keempat – TOK Oktober 2026 | D39: ABJ diminta menindaklanjuti kewajiban Knowledge Transfer kepada karyawan PAM JAYA sesuai PKS Greenfield, memberikan klarifikasi atas Surat ABJ 1064, serta memenuhi seluruh permintaan yang telah disampaikan melalui Surat PAM JAYA 4167 dan e-83482 | E39: Compliance - A. Levi
A40: 38 | B40: 4669/PS.04.04/EKST/IX/2026 | C40: Teguran atas Keterlambatan Penyampaian Dokumen Persyaratan Penyelesaian Proyek Greenfield atas seluruh Pekerjaan Fasilitas Distribusi Baru Yang Dijadwalkan untuk Paket Pekerjaan Kedua Tanggal Operasi Komersial 5 Oktober 2025 | D40: Teguran atas atas keterlambatan penyampaian DP3 untuk pekerjaan Fasilitas Distribusi Baru TOK 5 Oktober 2025, di mana dari 82 subprogram yang telah MC 100, baru 81 DP3 disampaikan dan 54 di antaranya melewati SLA. ABJ diminta segera menyelesaikan seluruh pekerjaan, menyampaikan 1 DP3 yang masih tertunda melalui BIM, serta memastikan tidak terjadi keterlambatan penyelesaian pekerjaan. | E40: PGO - Lusian F
A41: 39 | B41: 4670/PS.04.04/EKST/IX/2026 | C41: Teguran atas Keterlambatan Penyampaian Dokumen Persyaratan Penyelesaian Proyek Greenfield atas seluruh Pekerjaan Fasilitas Distribusi Baru Yang Dijadwalkan untuk Paket Pekerjaan Ketiga Tanggal Operasi Komersial 5 April 2026 | D41: Teguran atas keterlambatan penyampaian DP3 untuk pekerjaan Fasilitas Distribusi Baru TOK 5 April 2026, di mana dari 71 subprogram yang telah MC 100, baru 70 DP3 disampaikan dan 43 di antaranya melewati SLA. ABJ diminta menyelesaikan seluruh pekerjaan, segera menyampaikan 1 DP3 yang masih tertunda melalui BIM, serta memastikan tidak terjadi keterlambatan penyelesaian pekerjaan TOK 5 April 2026. | E41: PGO - Lusian F
A42: 40 | B42: 4654/PS.04.04/EKST/IX/2026 | C42: Teguran Penerapan Aspek Keselamatan dan Kesehatan Kerja ("K3") Proyek Greenfield Jatiluhur Hilir | D42: LOKASI TEMUAN 1. Paket PC 146, Lokasi JL Raden Inten, Jakarta timur | E42: HSE - Suhendro
A43: 41 | B43: 4653/PS.04.04/EKSI/IX/2026 | C43: Teguran Penerapan Aspek Keselamatan dan Kesehatan Kerja ("K3") Proyek Pembangunan Fasilitas Pendukung IPA Buaran 3 | D43: LOKASI TEMUAN 1. Proyek Pembangunan gedung workshop HC&GS area | E43: HSE - Suhendro
A44: 42 | B44: 4772/PS.04.01/EKST/IX/2026 | C44: Permintaan Pemenuhan Kewajiban Penyelesaian Project Greenfield | D44: Teguran atas ketidaksesuaian pelaksanaan Seluruh Paket Pekerjaan dengan dokumen pendukung, dan meminta ABJ menyelesaikan seluruh pekerjaan serta temuan/ketidaksesuaian, mengidentifikasi kendala dan mitigasi, memastikan kualitas pekerjaan, melengkapi dokumen untuk proses tagihan, serta memperbarui progress pekerjaan setiap minggu | E44: PMO Infill/PMO TM - Suci/Jusman
A45: 43 | B45: 4652/PS.04.04/EKST/IX/2026 | C45: Teguran Pemenuhan Kewajiban Penyelesaian Paket Pekerjaaan Keempat Proyek Greenfield Pada Saat Tanggal Operasi Komersial atau 5 Oktober 2026 | D45: Teguran atas ketidaksesuaian pelaksanaan pekerjaan Fasilitas Distribusi Baru TOK 5 Oktober 2026 dengan dokumen pendukung, dan meminta ABJ menyelesaikan seluruh pekerjaan serta temuan, mengidentifikasi kendala dan mitigasi, memastikan kualitas pekerjaan, melengkapi dokumen untuk proses tagihan, serta memperbarui progress pekerjaan setiap minggu. | E45: PMO Infill/PMO TM - Suci/Jusman
A46: 44 | B46: 4499/PS.04.04/EKST/IX/2026 | C46: Permintaan Rekomendasi atas Tindak Lanjut Program yang Tidak Dapat Dilaksanakan pada Setiap Paket Pekerjaaan Fasilitas Distribusi Baru yang Dijadwalkan Periode Tahun 2025-2026 | D46: Surat PAM JAYA ke KPI terkait dari 4 paket dengan target Operasi Komersial (Apr 2025 s/d Okt 2026), ditemukan 45 program tidak terlaksana oleh ABJ per cut off 15 Sept 2026 (Paket I: 9, II: 10, III: 17, IV: 9). PAM JAYA meminta KPI memberikan rekomendasi tindak lanjut atas program yang belum terlaksana. | E46: PGO - Lusian F
A47: 45 | B47: 4398/PS.04.01/EKST/IX/2026 | C47: Permintaan Tindak Lanjut Pembangunan Jaringan Pipa Pendukung Sistem DC Semanan SPAM Karian Serpong Hilir | D47: Pipa pendukung DC Semanan termasuk dalam proyek SPAM Karian Serpong Hilir. PAM JAYA menemukan segmen kritis pada desain ABJ, yaitu pipa eksisting PVC DN 500 di Joglo–Meruya Ilir. Segmen ini sudah mengalirkan 70 lps, dan jika ditambah rencana 178 lps kapasitasnya terlampaui. Head loss-nya mencapai 4 m/km, sedangkan batasnya 2 m/km. PAM JAYA meminta ABJ mengevaluasi ulang desain, memberi rekomendasi pemodelan hidrolis, dan memastikan pekerjaan selesai sebelum uji komisioning DC Semanan pada Mei 2027. | E47: Planning - Aji S
... A64: 62 | B64: 4776/PS.04.04/EKST/IX/2026 | C64: Teguran Penerapan Aspek Keselamatan dan Kesehatan Kerja ("K3") Proyek Greenfield Jatiluhur Hilir | D64: Hasil inspeksi K3 tanggal 28 Sep 2026 di PC 146 (Jl. Raden Inten & Jl. H. Naman, Jakarta Timur). Temuan: penempatan material mengganggu pengguna jalan, area proyek tidak rapi, pekerja tanpa APD, proteksi galian tidak sesuai standar, rambu tidak lengkap. | E64: HSE - Suhendro
A65: 63 | B65: 4759/PS.04.04/EKSI/IX/2026 | C65: Teguran Penerapan Aspek Keselamatan dan Kesehatan Kerja ("K3") Proyek Greenfield Jatiluhur Hilir & Buaran Hilir PC 146 & PC 160 Ez 5 | E65: HSE - Suhendro
A66: 64 | B66: 4758/PS.04.04/EKST/IX/2026 | C66: Teguran Penerapan Aspek Keselamatan dan Kesehatan Kerja ("K3") Proyek Greenfield Jatiluhur Hilir | D66: Hasil inspeksi K3 tanggal 24 Sep 2026 di S01 (Jl. Raya Pasar Minggu) dan S11 (Jl. Pahlawan Kalibata). Temuan: PPDU tidak sesuai standar PAM JAYA, pekerja tanpa APD, sisa tanah galian belum dirapikan, rambu tidak lengkap, water barrier di pit tidak memadai, papan informasi proyek tidak ada, tidak ada flagman, housekeeping tidak dilakukan. PAM JAYA menilai ini kelalaian ABJ yang menimbulkan citra negatif dan keluhan masyarakat (rujukan Pasal 8.11 PKS Greenfield). | E66: HSE - Suhendro
A67: 65 | B67: 4524/PS.04.01/EKST/IX/2026 | C67: Permintaan Pemenuhan Kewajiban | D67: PAM JAYA menyampaikan progres seluruh paket Greenfield per 16 Sep 2026: • TOK 5 Apr 2025: 125 program (107 BAST, 2 konstruksi, 6 pemeriksaan DPPP, 1 verifikasi KPI, 9 tidak dapat dilaksanakan) • TOK 5 Okt 2025: 108 program (17 konstruksi, 81 DPPP, 10 tidak dapat dilaksanakan) • TOK 5 Apr 2026: 108 program (21 konstruksi, 70 DPPP, 17 tidak dapat dilaksanakan) • TOK 5 Okt 2026: 96 program (75 konstruksi, 12 DPPP, 9 tidak dapat dilaksanakan) • Sambungan langsung baru tercapai ±34,73% dari target PKS Bundling (per 1 Sep 2026). PAM JAYA menegur ABJ atas ketidaksesuaian pelaksanaan dengan Program Konstruksi. | E67: PMO/PGO
...

Sheet Outgoing 2026
A1: No | B1: Nomor Surat | C1: Tanggal Surat | D1: Penerima | E1: Perihal | F1: Deskripsi | G1: Historical | H1: Produksi/Project | I1: Lokasi | J1: Kategori | K1: Due Date | L1: Status | M1: DIC | N1: PIC | O1: Durasi | P1: Durasi (Hari) | R1: =TODAY() -> 46304
A2: 1 | B2: ABJ/DIR/EKS/01.26/0001 | C2: 46024 | D2: PAM JAYA | E2: Usulan Diskusi Mengenai Konsultan Independen atas Perhitungan Tagihan KBA | H2: Project | I2: Greenfield | J2: Keuangan, Pembayaran, Investasi | L2: Closed | M2: Compliance | N2: Indradi | O2: =DATEDIF(C2,$R$1,"Y")&" tahun, "&DATEDIF(C2,$R$1,"YM")&" bulan, "&DATEDIF(C2,$R$1,"MD")&" hari" -> 0 tahun, 9 bulan, 7 hari | P2: =TODAY()-C2 -> 280
A3: 2 | B3: ABJ/DIR/EKS/01.26/0002 | C3: 46024 | D3: PAM JAYA | E3: Penyampaian Progres Penyelesaian Pekerjaan Program TOK 5 Oktober 2025 | H3: Project | I3: Greenfield | J3: Konstruksi Program Greenfield | L3: Info | M3: PGO | N3: Angelika | O3: =DATEDIF(C3,$R$1,"Y")&" tahun, "&DATEDIF(C3,$R$1,"YM")&" bulan, "&DATEDIF(C3,$R$1,"MD")&" hari" -> 0 tahun, 9 bulan, 7 hari | P3: =TODAY()-C3 -> 280
A4: 3 | B4: ABJ/DIR/EKS/01.26/0003 | C4: 46024 | D4: PAM JAYA | E4: Pemasangan Pipa Ramset Pada Program Master Meter Binton | H4: Project | I4: Jatiluhur Hilir | J4: Konstruksi Program Greenfield | L4: Info | M4: PMO Infill | N4: Muhrojin | O4: =DATEDIF(C4,$R$1,"Y")&" tahun, "&DATEDIF(C4,$R$1,"YM")&" bulan, "&DATEDIF(C4,$R$1,"MD")&" hari" -> 0 tahun, 9 bulan, 7 hari | P4: =TODAY()-C4 -> 280
A5: 4 | B5: ABJ/DIR/EKS/01.26/0004 | C5: 46024 | D5: KPI - PT Sucofindo | E5: Permintaan Laporan Verifikasi KPI atas Program Rehabilitasi Proyek Greenfield (IPA Buaran III) | H5: Project | I5: Buaran 3 Hulu | J5: Administrasi & Dokumentasi | L5: Open | M5: Compliance | N5: Indradi | O5: =DATEDIF(C5,$R$1,"Y")&" tahun, "&DATEDIF(C5,$R$1,"YM")&" bulan, "&DATEDIF(C5,$R$1,"MD")&" hari" -> 0 tahun, 9 bulan, 7 hari | P5: =TODAY()-C5 -> 280
A6: 5 | B6: ABJ/DIR/EKS/01.26/0009 | C6: 46027 | D6: Lurah Rawamangun | E6: Surat Pemberitahuan | H6: Project | I6: Greenfield | J6: Konstruksi Program Greenfield | L6: Info | M6: PMO TM | N6: Suci | O6: =DATEDIF(C6,$R$1,"Y")&" tahun, "&DATEDIF(C6,$R$1,"YM")&" bulan, "&DATEDIF(C6,$R$1,"MD")&" hari" -> 0 tahun, 9 bulan, 4 hari | P6: =TODAY()-C6 -> 277
A7: 6 | B7: ABJ/DIR/EKS/01.26/0010 | C7: 46027 | D7: PAM JAYA | E7: Tagihan Air Curah Perjanjian Brownfield – Periode Desember 2025 | H7: Corporate | I7: Corporate | J7: Keuangan, Pembayaran, Investasi | L7: Closed | M7: Compliance | N7: Indradi | O7: =DATEDIF(C7,$R$1,"Y")&" tahun, "&DATEDIF(C7,$R$1,"YM")&" bulan, "&DATEDIF(C7,$R$1,"MD")&" hari" -> 0 tahun, 9 bulan, 4 hari | P7: =TODAY()-C7 -> 277
A8: 7 | B8: ABJ/DIR/EKS/01.26/0011 | C8: 46027 | D8: PAM JAYA | E8: Tagihan Air Curah Perjanjian Greenfield - Periode Desember 2025 | H8: Corporate | I8: Corporate | J8: Keuangan, Pembayaran, Investasi | L8: Closed | M8: Compliance | N8: Indradi | O8: =DATEDIF(C8,$R$1,"Y")&" tahun, "&DATEDIF(C8,$R$1,"YM")&" bulan, "&DATEDIF(C8,$R$1,"MD")&" hari" -> 0 tahun, 9 bulan, 4 hari | P8: =TODAY()-C8 -> 277
A9: 8 | B9: ABJ/DIR/EKS/01.26/0012 | C9: 46027 | D9: PAM JAYA | E9: Pembaharuan Informasi Dokumen Persyaratan Penyelesaian Pekerjaan Fasilitas Distribusi Baru Paket Kedua TOK Oktober 2025 | H9: Project | I9: Greenfield | J9: Administrasi & Dokumentasi | L9: Info | M9: PGO | N9: Angelika | O9: =DATEDIF(C9,$R$1,"Y")&" tahun, "&DATEDIF(C9,$R$1,"YM")&" bulan, "&DATEDIF(C9,$R$1,"MD")&" hari" -> 0 tahun, 9 bulan, 4 hari | P9: =TODAY()-C9 -> 277
A10: 9 | B10: ABJ/DIR/EKS/01.26/0013 | C10: 46027 | D10: PAM JAYA | E10: Laporan Bulanan Kualitas Air Baku dan Air Curah Periode Desember 2025 | H10: Produksi | I10: ALL WTP | J10: Monitoring & Pelaporan | L10: Info | M10: WQA | N10: Novi | O10: =DATEDIF(C10,$R$1,"Y")&" tahun, "&DATEDIF(C10,$R$1,"YM")&" bulan, "&DATEDIF(C10,$R$1,"MD")&" hari" -> 0 tahun, 9 bulan, 4 hari | P10: =TODAY()-C10 -> 277
A11: 10 | B11: ABJ/DIR/EKS/01.26/0014 | C11: 46027 | D11: Direktur Jenderal Administrasi Hukum Umum cq. Direktur Badan Usaha Kementerian Hukum | E11: Permohonan Perbaikan Data Email dan Nomor Telepon PT AIR BERSIH JAKARTA | H11: Corporate | I11: Corporate | J11: Kontrak & Legal | L11: Info | M11: Legal - Moya | N11: Angelina | O11: =DATEDIF(C11,$R$1,"Y")&" tahun, "&DATEDIF(C11,$R$1,"YM")&" bulan, "&DATEDIF(C11,$R$1,"MD")&" hari" -> 0 tahun, 9 bulan, 4 hari | P11: =TODAY()-C11 -> 277
A12: 11 | B12: ABJ/DIR/EKS/01.26/0015 | C12: 46028 | D12: Bank OCBC NISP, Tbk - Agency & Trust Services | E12: Penyampaian Salinan Asli Polis Asuransi | H12: Corporate | I12: Corporate | J12: Keuangan, Pembayaran, Investasi | L12: Info | M12: Finance | N12: Nurul S | O12: =DATEDIF(C12,$R$1,"Y")&" tahun, "&DATEDIF(C12,$R$1,"YM")&" bulan, "&DATEDIF(C12,$R$1,"MD")&" hari" -> 0 tahun, 9 bulan, 3 hari | P12: =TODAY()-C12 -> 276
A13: 12 | B13: ABJ/DIR/EKS/01.26/0016 | C13: 46028 | D13: PT Bank Central Asia Tbk | E13: Permohonan Penghapusan Lampiran 6 Step-In dalam Persyaratan Lebih Lanjut | H13: Corporate | I13: Corporate | J13: Kontrak & Legal | L13: Info | M13: Legal | N13: Bahtera N | O13: =DATEDIF(C13,$R$1,"Y")&" tahun, "&DATEDIF(C13,$R$1,"YM")&" bulan, "&DATEDIF(C13,$R$1,"MD")&" hari" -> 0 tahun, 9 bulan, 3 hari | P13: =TODAY()-C13 -> 276
... A28: 27 | B28: ABJ/DIR/EKS/01.26/0030 | C28: 46031 | D28: PAM JAYA | E28: Undangan Uji Komisioning SPAM Jatiluhur Hilir – JDU JDB JDL PC 054 Oran Danarsio | H28: Project | I28: Jatiluhur Hilir | J28: Konstruksi Program Greenfield | L28: Info | M28: PMO Infill | N28: Muhrojin | O28: =DATEDIF(C28,$R$1,"Y")&" tahun, "&DATEDIF(C28,$R$1,"YM")&" bulan, "&DATEDIF(C28,$R$1,"MD")&" hari" -> 0 tahun, 9 bulan, 0 hari | P28: =TODAY()-C28 -> 273
A29: 28 | B29: ABJ/DIR/EKS/01.26/0031 | C29: 46031 | D29: PAM JAYA | E29: Permintaan Pengembalian Dana Cadangan Terkait Proyek Brownfield | G29: Menanggapi surat masuk: PJ 2495.PS.04.02-EKST.VI.2026 - Tanggapan atas Permintaan Pengembalian Dana Cadangan | H29: Project | I29: Cyclical | J29: Keuangan, Pembayaran, Investasi | L29: Open | M29: Legal | N29: Bahtera N | O29: =DATEDIF(C29,$R$1,"Y")&" tahun, "&DATEDIF(C29,$R$1,"YM")&" bulan, "&DATEDIF(C29,$R$1,"MD")&" hari" -> 0 tahun, 9 bulan, 0 hari | P29: =TODAY()-C29 -> 273
A30: 29 | B30: ABJ/DIR/EKS/01.26/0033 | C30: 46034 | D30: PAM JAYA | E30: Permohonan Pemakaian Air PAM JAYA untuk hydrotest seq 5,6,7 & 8 Proyek SPAM Pesanggrahan (Paket TMPSG Jalur 01) | H30: Project | I30: Karian Serpong Hilir | J30: Konstruksi Program Greenfield | L30: Info | M30: PMO TM | N30: Suci | O30: =DATEDIF(C30,$R$1,"Y")&" tahun, "&DATEDIF(C30,$R$1,"YM")&" bulan, "&DATEDIF(C30,$R$1,"MD")&" hari" -> 0 tahun, 8 bulan, 27 hari | P30: =TODAY()-C30 -> 270
A31: 30 | B31: ABJ/DIR/EKS/01.26/0034 | C31: 46034 | D31: PAM JAYA | E31: Permintaan Target Kesepakatan Mengenai Alur Proses Penyelesaian Sambungan Langsung | H31: Project | I31: Greenfield | J31: Sambungan Langsung | L31: Open | M31: PMO NC | N31: A. Levi | O31: =DATEDIF(C31,$R$1,"Y")&" tahun, "&DATEDIF(C31,$R$1,"YM")&" bulan, "&DATEDIF(C31,$R$1,"MD")&" hari" -> 0 tahun, 8 bulan, 27 hari | P31: =TODAY()-C31 -> 270
A32: 31 | B32: ABJ/DIR/EKS/01.26/0035 | C32: 46034 | D32: PAM JAYA | E32: Usulan Penyederhanaan Workflow Desain Akhir, Proposal Modifikasi, dan Closing melalui BIM | G32: Ditanggapi oleh surat masuk: PJ e-72734.PS.04.00 Tanggapan atas Surat ABJ26 0035 tanggal 12 Januari 2026 Perihal Usulan Penyederhanaan Workflow Desain Akhir, Proposal Modifikasi, dan Closing melalui BIM | H32: Project | I32: Project | J32: Administrasi & Dokumentasi | L32: Closed | M32: PGO | N32: Angelika | O32: =DATEDIF(C32,$R$1,"Y")&" tahun, "&DATEDIF(C32,$R$1,"YM")&" bulan, "&DATEDIF(C32,$R$1,"MD")&" hari" -> 0 tahun, 8 bulan, 27 hari | P32: =TODAY()-C32 -> 270
A33: 32 | B33: ABJ/DIR/EKS/01.26/0036 | C33: 46035 | D33: PT. Bina Lestari Lingkungan Sejahtera | E33: Surat Teguran Atas Pelaksanaan Tugas Konsultan Manajemen Konstruksi | H33: Project | I33: Project | J33: Konstruksi Program Greenfield | L33: Info | M33: PGO | N33: Angelika | O33: =DATEDIF(C33,$R$1,"Y")&" tahun, "&DATEDIF(C33,$R$1,"YM")&" bulan, "&DATEDIF(C33,$R$1,"MD")&" hari" -> 0 tahun, 8 bulan, 26 hari | P33: =TODAY()-C33 -> 269
A34: 33 | B34: ABJ/DIR/EKS/01.26/0037 | C34: 46035 | D34: PAM JAYA | E34: Tanggapan atas Surat PAM JAYA No. e-70776/PP.01.04 Perihal Sanksi Denda atas Kegagalan Kinerja Periode Bulan November 2025 | G34: Menanggapi surat masuk: PJ e-70776.PP.01.04 - Sanksi Denda atas Kegagalan Kinerja Periode Bulan November 2025; PJ e-70776.PP.01.04 Sanksi Denda atas Kegagalan Kinerja Periode Bulan November 2025; PJ e-82079.PP.01.04 - Tanggapan atas Surat ABJ 0714 Perihal Tanggapan Atas Surat PAM JAYA Nomor e-59697 Tentang Sanksi Denda Kegagalan Kinerja Periode Bulan Juni 2025 | H34: Produksi | I34: PJP 1 | J34: Denda & Kegagalan | L34: Info | M34: Compliance | N34: Indradi | O34: =DATEDIF(C34,$R$1,"Y")&" tahun, "&DATEDIF(C34,$R$1,"YM")&" bulan, "&DATEDIF(C34,$R$1,"MD")&" hari" -> 0 tahun, 8 bulan, 26 hari | P34: =TODAY()-C34 -> 269
A35: 34 | B35: ABJ/DIR/EKS/01.26/0038 | C35: 46035 | D35: PAM JAYA | E35: Pembaharuan DED dan RAB Proyek SPAM Ciliwung Hilir – Tahap Kedua | H35: Project | I35: Jatiluhur Hilir | J35: Perencanaan Program Greenfield | L35: Info | M35: Planning | N35: Aji S | O35: =DATEDIF(C35,$R$1,"Y")&" tahun, "&DATEDIF(C35,$R$1,"YM")&" bulan, "&DATEDIF(C35,$R$1,"MD")&" hari" -> 0 tahun, 8 bulan, 26 hari | P35: =TODAY()-C35 -> 269
A36: 35 | B36: ABJ/DIR/EKS/01.26/0039 | C36: 46036 | D36: Kelurahan Pesanggrahan | E36: Pemberitahuan Kegiatan Pekerjaan Galian Pipa di wilayah Kelurahan Pesanggrahan | H36: Project | I36: Karian Serpong Hilir | J36: Koordinasi & Sosialisasi | L36: Info | M36: Permit | N36: Rudy | O36: =DATEDIF(C36,$R$1,"Y")&" tahun, "&DATEDIF(C36,$R$1,"YM")&" bulan, "&DATEDIF(C36,$R$1,"MD")&" hari" -> 0 tahun, 8 bulan, 25 hari | P36: =TODAY()-C36 -> 268
A37: 36 | B37: ABJ/DIR/EKS/01.26/0040 | C37: 46036 | D37: PAM JAYA | E37: Penyampaian Laporan Penyelesaian Uji Komisioning Project Greenfield – SPAM Jatiluhur Hilir 9 Program | G37: Ditanggapi oleh surat masuk: 153/SCI-KPI/I/2026 - Penyampaian Laporan Penyelesaian Uji Komisioning Project Greenfield – SPAM Jatiluhur Hilir 9 Program | H37: Project | I37: Jatiluhur Hilir | J37: Konstruksi Program Greenfield | L37: Info | M37: PMO Infill | N37: Muhrojin | O37: =DATEDIF(C37,$R$1,"Y")&" tahun, "&DATEDIF(C37,$R$1,"YM")&" bulan, "&DATEDIF(C37,$R$1,"MD")&" hari" -> 0 tahun, 8 bulan, 25 hari | P37: =TODAY()-C37 -> 268
A38: 37 | B38: ABJ/DIR/EKS/01.26/0041 | C38: 46036 | D38: PAM JAYA | E38: Percepatan Peningkatan Cakupan Layanan Air Minum melalui Sambungan Langsung DKI Jakarta | H38: Project | I38: Greenfield | J38: Sambungan Langsung | L38: Info | M38: PMO NC | N38: A. Levi | O38: =DATEDIF(C38,$R$1,"Y")&" tahun, "&DATEDIF(C38,$R$1,"YM")&" bulan, "&DATEDIF(C38,$R$1,"MD")&" hari" -> 0 tahun, 8 bulan, 25 hari | P38: =TODAY()-C38 -> 268
A39: 38 | B39: ABJ/DIR/EKS/01.26/0042 | C39: 46036 | D39: Komandan Batalyon Arhanud 10/ABC | E39: Pemberitahuan Kegiatan Pekerjaan Galian Pipa di wilayah Batalyon Arhanud 10/ABC | H39: Project | I39: Greenfield | J39: Koordinasi & Sosialisasi | L39: Info | M39: Permit | N39: Rudy | O39: =DATEDIF(C39,$R$1,"Y")&" tahun, "&DATEDIF(C39,$R$1,"YM")&" bulan, "&DATEDIF(C39,$R$1,"MD")&" hari" -> 0 tahun, 8 bulan, 25 hari | P39: =TODAY()-C39 -> 268
A40: 39 | B40: ABJ/DIR/EKS/01.26/0043 | C40: 46036 | D40: Badan Pengelola Perumahan Cirendeu Permai | E40: Permohonan ijin akses jalan menuju Reservoir DCR 5 | H40: Project | I40: Greenfield | J40: Koordinasi & Sosialisasi | L40: Info | M40: PMO TM | N40: Suci | O40: =DATEDIF(C40,$R$1,"Y")&" tahun, "&DATEDIF(C40,$R$1,"YM")&" bulan, "&DATEDIF(C40,$R$1,"MD")&" hari" -> 0 tahun, 8 bulan, 25 hari | P40: =TODAY()-C40 -> 268
A41: 40 | B41: ABJ/DIR/EKS/01.26/0044 | C41: 46036 | D41: PAM JAYA | E41: Tanggapan atas Surat PAM JAYA No. e-70215/PS.00.04 Perihal Permintaan Bukti Penyimpanan Dokumen | G41: PJ e-70215.PS.00.04 PJ e-84086-PP.01.05 e-74895-PS.04.03 | H41: Corporate | I41: Corporate | J41: Administrasi & Dokumentasi | L41: Info | M41: Compliance | N41: Indradi | O41: =DATEDIF(C41,$R$1,"Y")&" tahun, "&DATEDIF(C41,$R$1,"YM")&" bulan, "&DATEDIF(C41,$R$1,"MD")&" hari" -> 0 tahun, 8 bulan, 25 hari | P41: =TODAY()-C41 -> 268
A42: 41 | B42: ABJ/DIR/EKS/01.26/0045 | C42: 46037 | D42: PAM JAYA | E42: Penundaan Pelaksanaan Proyek Pembangunan Pipa A4 Marunda | H42: Project | I42: Jatiluhur Hilir | J42: Konstruksi Program Greenfield | L42: Info | M42: Planning | N42: Aji S | O42: =DATEDIF(C42,$R$1,"Y")&" tahun, "&DATEDIF(C42,$R$1,"YM")&" bulan, "&DATEDIF(C42,$R$1,"MD")&" hari" -> 0 tahun, 8 bulan, 24 hari | P42: =TODAY()-C42 -> 267
A43: 42 | B43: ABJ/DIR/EKS/01.26/0046 | C43: 46037 | D43: PAM JAYA | E43: Penyampaian Dokumen Polis Asuransi Project Brownfield & Greenfield | G43: Menanggapi surat masuk: e-70216/PS.04.03 - Konfirmasi Perpanjangan Polis Asuransi Project Brownfield & Greenfield | H43: Project | I43: Project | J43: Keuangan, Pembayaran, Investasi | L43: Info | M43: Finance | N43: Nurul s | O43: =DATEDIF(C43,$R$1,"Y")&" tahun, "&DATEDIF(C43,$R$1,"YM")&" bulan, "&DATEDIF(C43,$R$1,"MD")&" hari" -> 0 tahun, 8 bulan, 24 hari | P43: =TODAY()-C43 -> 267
A44: 43 | B44: ABJ/DIR/EKS/01.26/0047 | C44: 46037 | D44: PAM JAYA | E44: Penyampaian Informasi Pembatalan Program Flow Meter Air Baku (Program Cyclical tahun 2026) | H44: Project | I44: Cyclical | J44: Konstruksi Program Greenfield | L44: Info | M44: PMO Cyclical | N44: Agus Herdinand | O44: =DATEDIF(C44,$R$1,"Y")&" tahun, "&DATEDIF(C44,$R$1,"YM")&" bulan, "&DATEDIF(C44,$R$1,"MD")&" hari" -> 0 tahun, 8 bulan, 24 hari | P44: =TODAY()-C44 -> 267
A45: 44 | B45: ABJ/DIR/EKS/01.26/0048 | C45: 46037 | D45: PAM JAYA | E45: Tanggapan Surat PAM JAYA No e-67973/PP.00.04 Perihal Biaya Persiapan Proyek Greenfield Tahun 2025-2031 | G45: e-67973/PP.00.04 | H45: Project | I45: Greenfield | J45: Perencanaan Program Greenfield | L45: Info | M45: Planning | N45: Andriani | O45: =DATEDIF(C45,$R$1,"Y")&" tahun, "&DATEDIF(C45,$R$1,"YM")&" bulan, "&DATEDIF(C45,$R$1,"MD")&" hari" -> 0 tahun, 8 bulan, 24 hari | P45: =TODAY()-C45 -> 267
A46: 45 | B46: ABJ/DIR/EKS/01.26/0049 | C46: 46037 | D46: PT. Bina Lestari Lingkungan Sejahtera | E46: Surat Peringatan Akibat Kegagalan Pengawasan BLLS | H46: Project | I46: Project | J46: Konstruksi Program Greenfield | L46: Info | M46: PMO Infill | N46: Danny L | O46: =DATEDIF(C46,$R$1,"Y")&" tahun, "&DATEDIF(C46,$R$1,"YM")&" bulan, "&DATEDIF(C46,$R$1,"MD")&" hari" -> 0 tahun, 8 bulan, 24 hari | P46: =TODAY()-C46 -> 267
A47: 46 | B47: ABJ/DIR/EKS/01.26/0050 | C47: 46037 | D47: PT. Infratama Yakti | E47: Surat Peringatan Akibat Kegagalan Infratama | H47: Project | I47: Project | J47: Konstruksi Program Greenfield | L47: Info | M47: PMO Infill | N47: Danny L | O47: =DATEDIF(C47,$R$1,"Y")&" tahun, "&DATEDIF(C47,$R$1,"YM")&" bulan, "&DATEDIF(C47,$R$1,"MD")&" hari" -> 0 tahun, 8 bulan, 24 hari | P47: =TODAY()-C47 -> 267
A48: 47 | B48: ABJ/DIR/EKS/01.26/0051 | C48: 46037 | D48: PAM JAYA | E48: Pengiriman Tanggapan Atas Hasil Review PAM dan KPI Terhadap Dokumen Desain Akhir Program Rehabilitasi Tahun 2026 | H48: Project | I48: Cyclical | J48: Perencanaan Program Rehabilitasi | L48: Info | M48: PMO Cyclical | N48: Agus Herdinand | O48: =DATEDIF(C48,$R$1,"Y")&" tahun, "&DATEDIF(C48,$R$1,"YM")&" bulan, "&DATEDIF(C48,$R$1,"MD")&" hari" -> 0 tahun, 8 bulan, 24 hari | P48: =TODAY()-C48 -> 267
A49: 48 | B49: ABJ/DIR/EKS/01.26/0052 | C49: 46037 | D49: PAM JAYA | E49: Undangan Uji Komisioning SPAM Jatiluhur Hilir – JDU JDB JDL PC 049 Cluster Alexandria, PC 054 H.Sutiyo dan PC 054 Rawa Badung RW 07 | H49: Project | I49: Jatiluhur Hilir | J49: Konstruksi Program Greenfield | L49: Info | M49: PMO Infill | N49: Muhrojin | O49: =DATEDIF(C49,$R$1,"Y")&" tahun, "&DATEDIF(C49,$R$1,"YM")&" bulan, "&DATEDIF(C49,$R$1,"MD")&" hari" -> 0 tahun, 8 bulan, 24 hari | P49: =TODAY()-C49 -> 267
A50: 49 | B50: ABJ/DIR/EKS/01.26/0053 | C50: 46041 | D50: PAM JAYA | E50: Penyampaian Laporan Pengawasan dan Laporan Perkembangan Proyek Kuartal 4 Tahun 2025 | H50: Project | I50: Project | J50: Monitoring & Pelaporan | L50: Info | M50: Compliance | N50: Indradi | O50: =DATEDIF(C50,$R$1,"Y")&" tahun, "&DATEDIF(C50,$R$1,"YM")&" bulan, "&DATEDIF(C50,$R$1,"MD")&" hari" -> 0 tahun, 8 bulan, 20 hari | P50: =TODAY()-C50 -> 263
A51: 50 | B51: ABJ/DIR/EKS/01.26/0054 | C51: 46041 | D51: PAM JAYA | E51: Pemasangan Pipa Ramset Pada Program Master Meter Binton | H51: Project | I51: Jatiluhur Hilir | J51: Konstruksi Program Greenfield | L51: Info | M51: PMO Infill | N51: Muhrojin | O51: =DATEDIF(C51,$R$1,"Y")&" tahun, "&DATEDIF(C51,$R$1,"YM")&" bulan, "&DATEDIF(C51,$R$1,"MD")&" hari" -> 0 tahun, 8 bulan, 20 hari | P51: =TODAY()-C51 -> 263
A52: 51 | B52: ABJ/DIR/EKS/01.26/0055 | C52: 46041 | D52: Dinas Pertamanan dan Hutan Kota | E52: Pernyataan Permohonan Izin Tebang Mendahului & Kesanggupan Penggantian Pohon | H52: Project | I52: Greenfield | J52: Koordinasi & Sosialisasi | L52: Info | M52: PMO TM | N52: Suci | O52: =DATEDIF(C52,$R$1,"Y")&" tahun, "&DATEDIF(C52,$R$1,"YM")&" bulan, "&DATEDIF(C52,$R$1,"MD")&" hari" -> 0 tahun, 8 bulan, 20 hari | P52: =TODAY()-C52 -> 263
A53: 52 | B53: ABJ/DIR/EKS/01.26/0056 | C53: 46041 | D53: PAM JAYA | E53: Penyampaian Biaya Persiapan dan Pembaharuan Nilai Desain Akhir Proyek Greenfield | H53: Project | I53: Greenfield | J53: Perencanaan Program Greenfield | L53: Info | M53: Planning | N53: Aji S | O53: =DATEDIF(C53,$R$1,"Y")&" tahun, "&DATEDIF(C53,$R$1,"YM")&" bulan, "&DATEDIF(C53,$R$1,"MD")&" hari" -> 0 tahun, 8 bulan, 20 hari | P53: =TODAY()-C53 -> 263
A54: 53 | B54: ABJ/DIR/EKS/01.26/0057 | C54: 46041 | D54: PAM JAYA | E54: Undangan Uji Komisioning SPAM Buaran III Hilir – JDU JDB JDL PC 161 Anwar Burhanudin | H54: Project | I54: Buaran 3 Hilir | J54: Konstruksi Program Greenfield | L54: Info | M54: PMO Infill | N54: Topan | O54: =DATEDIF(C54,$R$1,"Y")&" tahun, "&DATEDIF(C54,$R$1,"YM")&" bulan, "&DATEDIF(C54,$R$1,"MD")&" hari" -> 0 tahun, 8 bulan, 20 hari | P54: =TODAY()-C54 -> 263
...

Sheet Incoming 2026
A1: No | B1: Nomor Surat | C1: Tanggal Diterima | D1: Tanggal Surat | E1: Pengirim | F1: Perihal | G1: Deskripsi | H1: Produksi/Project | I1: Lokasi | J1: Kategori | K1: Perlu di balas | L1: Status | M1: Level Status | N1: Tindak Lanjut | O1: Dibalas oleh Surat ABJ Nomor | P1: Historical | Q1: Due Date | R1: DIC | S1: PIC | T1: Durasi | U1: Durasi (hari) | W1: Durasi Keterlambatan | X1: Durasi Deadline | Z1: =TODAY() -> 46304
A2: 1 | B2: 144/SCI-KPI/I/2026 | C2: 46027 | D2: 46024 | E2: KPI - Sucofindo | F2: Tanggapan atas Surat PT Air Bersih Jakarta No. ABJ/DIR/EKS/12.25/1126 Tentang Penyampaian Laporan Penyelesaian Uji Komisioning Project Greenfield - SPAM Karian Serpong Hilir Program Arman, Puspa, Porto | G2: Dokumen yang belum lengkap agar dilengkapi pada saat MC100 | H2: Project | I2: Karian Serpong Hilir | J2: Konstruksi Program Greenfield | K2: Tidak | L2: Info | M2: Info | P2: ABJ/DIR/EKS/12.25/1126 | R2: PMO Infill | S2: Ervin Y | T2: =DATEDIF(C2,$Z$1,"Y")&" tahun, "&DATEDIF(C2,$Z$1,"YM")&" bulan, "&DATEDIF(C2,$Z$1,"MD")&" hari" -> 0 tahun, 9 bulan, 4 hari | U2: =DATEDIF(C2,Summary!$A$1,"d") -> 277 | W2: {=_xlfn.IFS(U2<=X2,X2,U2<=X2*2,X2*2,U2<=X2*3,X2*3,U2>X2*3,">"&X2*3)} -> Info | X2: {=_xlfn.IFS(M2="Level 1",7,M2="Level 2",14,M2="Level 3","30",M2="Info","Info",M2="Closed","Closed")} -> Info
A3: 2 | B3: e-70214/PP.00.02 | C3: 46028 | D3: 46009 | E3: PAM JAYA | F3: Pemutakhiran Desain Akhir JDU JDB JDL dan SL Proyek Greenfield Regional Barat, Selatan, Utara, Pusat | G3: PAM JAYA meminta ABJ untuk melakukan survey sesuai lokasi pada surat terlampir | H3: Project | I3: Greenfield | J3: Perencanaan Program Greenfield | K3: Ya | L3: Closed | M3: Closed | O3: ABJ/DIR/EKS/08.26/0981 , ABJ/DIR/EKS/04.26/0377, ABJ/DIR/EKS/07.26/0845 | P3: ABJ/DIR/EKS/08.26/0981 , ABJ/DIR/EKS/04.26/0377, ABJ/DIR/EKS/07.26/0845 | R3: Planning | S3: Aji S | T3: =DATEDIF(C3,$Z$1,"Y")&" tahun, "&DATEDIF(C3,$Z$1,"YM")&" bulan, "&DATEDIF(C3,$Z$1,"MD")&" hari" -> 0 tahun, 9 bulan, 3 hari | U3: =DATEDIF(C3,Summary!$A$1,"d") -> 276 | V3: lewat 30d | W3: {=_xlfn.IFS(U3<=X3,X3,U3<=X3*2,X3*2,U3<=X3*3,X3*3,U3>X3*3,">"&X3*3)} -> Closed | X3: {=_xlfn.IFS(M3="Level 1",7,M3="Level 2",14,M3="Level 3","30",M3="Info","Info",M3="Closed","Closed")} -> Closed
A4: 3 | B4: e-70215/PS.00.04 | C4: 46028 | D4: 46008 | E4: PAM JAYA | F4: Permintaan Bukti Penyimpanan Dokumen | G4: PAM JAYA meminta bukti penyimpanan dokumen selambatnya 7 hari sejak surat diterima | H4: Corporate | I4: Corporate | J4: Administrasi & Dokumentasi | K4: Ya | L4: Closed | M4: Closed | O4: ABJ/DIR/EKS/01.26/0044 | P4: ABJ/DIR/EKS/01.26/0044 | R4: Compliance | S4: Indradi | T4: =DATEDIF(C4,$Z$1,"Y")&" tahun, "&DATEDIF(C4,$Z$1,"YM")&" bulan, "&DATEDIF(C4,$Z$1,"MD")&" hari" -> 0 tahun, 9 bulan, 3 hari | U4: =DATEDIF(C4,Summary!$A$1,"d") -> 276 | W4: {=_xlfn.IFS(U4<=X4,X4,U4<=X4*2,X4*2,U4<=X4*3,X4*3,U4>X4*3,">"&X4*3)} -> Closed | X4: {=_xlfn.IFS(M4="Level 1",7,M4="Level 2",14,M4="Level 3","30",M4="Info","Info",M4="Closed","Closed")} -> Closed
A5: 4 | B5: e-70217/PP.00.02 | C5: 46028 | D5: 46013 | E5: PAM JAYA | F5: Percepatan Pelaksanaan Program JDU+JDB+JDL dan Sambungan Langsung di Area Prioritas Regional Utara (Pantai Mutiara, Kp. Muka, Kp. Kerang Hijau Muara Angke) | G5: PAM JAYA meminta percepatan pekerjaan dan SL pada lokasi surat terlampir | H5: Project | I5: Greenfield | J5: Sambungan Langsung | K5: Ya | L5: Open | M5: Level 2 | R5: Planning | S5: Aji S | T5: =DATEDIF(C5,$Z$1,"Y")&" tahun, "&DATEDIF(C5,$Z$1,"YM")&" bulan, "&DATEDIF(C5,$Z$1,"MD")&" hari" -> 0 tahun, 9 bulan, 3 hari | U5: =DATEDIF(C5,Summary!$A$1,"d") -> 276 | V5: lewat 30d | W5: {=_xlfn.IFS(U5<=X5,X5,U5<=X5*2,X5*2,U5<=X5*3,X5*3,U5>X5*3,">"&X5*3)} -> >42 | X5: {=_xlfn.IFS(M5="Level 1",7,M5="Level 2",14,M5="Level 3","30",M5="Info","Info",M5="Closed","Closed")} -> 14
A6: 5 | B6: e-70229/PP.00.02 | C6: 46028 | D6: 46013 | E6: PAM JAYA | F6: Pemutakhiran Desain Akhir Proyek Greenfield IPA Portable Semanan | G6: PAM JAYA meminta untuk dilakukan survei bersama pada lokasi terlampir | H6: Project | I6: Greenfield | J6: Perencanaan Program Greenfield | K6: Ya | L6: Open | M6: Level 2 | R6: Planning | S6: Aji S | T6: =DATEDIF(C6,$Z$1,"Y")&" tahun, "&DATEDIF(C6,$Z$1,"YM")&" bulan, "&DATEDIF(C6,$Z$1,"MD")&" hari" -> 0 tahun, 9 bulan, 3 hari | U6: =DATEDIF(C6,Summary!$A$1,"d") -> 276 | V6: lewat 30d | W6: {=_xlfn.IFS(U6<=X6,X6,U6<=X6*2,X6*2,U6<=X6*3,X6*3,U6>X6*3,">"&X6*3)} -> >42 | X6: {=_xlfn.IFS(M6="Level 1",7,M6="Level 2",14,M6="Level 3","30",M6="Info","Info",M6="Closed","Closed")} -> 14
A7: 6 | B7: e-68122/PP.00.02 | C7: 46028 | D7: 45987 | E7: PAM JAYA | F7: Pemutakhiran Desain Akhir JDU JDB JDL dan SL Proyek Greenfield Corporate Customer Regional Timur | G7: PAM JAYA meminta untuk dilakukan survei bersama pada lokasi di surat terlampir | H7: Project | I7: Greenfield | J7: Perencanaan Program Greenfield | K7: Ya | L7: Open | M7: Level 2 | R7: Planning | S7: Aji S | T7: =DATEDIF(C7,$Z$1,"Y")&" tahun, "&DATEDIF(C7,$Z$1,"YM")&" bulan, "&DATEDIF(C7,$Z$1,"MD")&" hari" -> 0 tahun, 9 bulan, 3 hari | U7: =DATEDIF(C7,Summary!$A$1,"d") -> 276 | V7: lewat 30d | W7: {=_xlfn.IFS(U7<=X7,X7,U7<=X7*2,X7*2,U7<=X7*3,X7*3,U7>X7*3,">"&X7*3)} -> >42 | X7: {=_xlfn.IFS(M7="Level 1",7,M7="Level 2",14,M7="Level 3","30",M7="Info","Info",M7="Closed","Closed")} -> 14
A8: 7 | B8: e-70620/PP.00.02 | C8: 46028 | E8: PAM JAYA | F8: Pemutakhiran Desain Akhir JDU JDB JDL dan SL Proyek Greenfield Regional Utara dan Selatan | H8: Project | I8: Greenfield | J8: Perencanaan Program Greenfield | K8: Ya | L8: Open | M8: Level 2 | R8: Planning | S8: Aji S | T8: =DATEDIF(C8,$Z$1,"Y")&" tahun, "&DATEDIF(C8,$Z$1,"YM")&" bulan, "&DATEDIF(C8,$Z$1,"MD")&" hari" -> 0 tahun, 9 bulan, 3 hari | U8: =DATEDIF(C8,Summary!$A$1,"d") -> 276 | V8: lewat 30d | W8: {=_xlfn.IFS(U8<=X8,X8,U8<=X8*2,X8*2,U8<=X8*3,X8*3,U8>X8*3,">"&X8*3)} -> >42 | X8: {=_xlfn.IFS(M8="Level 1",7,M8="Level 2",14,M8="Level 3","30",M8="Info","Info",M8="Closed","Closed")} -> 14
A9: 8 | B9: 4720/PP.01.03/EKST/XII/2025 | C9: 46028 | D9: 46022 | E9: PAM JAYA | F9: Permintaan Pemenuhan Kewajiban Penyelesaian Paket Pekerjaan Kedua Proyek Greenfield pada saat Tanggal Operasi Komersial atau 5 Oktober 2025 | G9: Informasi project TOK 5 Oktober dan PAM JAYA meminta untuk memenuhi seluruh pekerjaan dan seluruh dokumen | H9: Project | I9: Greenfield | J9: Konstruksi Program Greenfield | K9: Tidak | L9: Info | M9: Info | R9: PMO Infill | S9: Danny L | T9: =DATEDIF(C9,$Z$1,"Y")&" tahun, "&DATEDIF(C9,$Z$1,"YM")&" bulan, "&DATEDIF(C9,$Z$1,"MD")&" hari" -> 0 tahun, 9 bulan, 3 hari | U9: =DATEDIF(C9,Summary!$A$1,"d") -> 276 | W9: {=_xlfn.IFS(U9<=X9,X9,U9<=X9*2,X9*2,U9<=X9*3,X9*3,U9>X9*3,">"&X9*3)} -> Info | X9: {=_xlfn.IFS(M9="Level 1",7,M9="Level 2",14,M9="Level 3","30",M9="Info","Info",M9="Closed","Closed")} -> Info
A10: 9 | B10: e-70216/PS.04.03 | C10: 46028 | D10: 46007 | E10: PAM JAYA | F10: Konfirmasi Perpanjangan Polis Asuransi Project Brownfield & Greenfield | G10: Konfirmasi rencana perpanjangan polis dalam jangka waktu 3 hari kalender | H10: Project | I10: Project | J10: Kontrak & Legal | K10: Ya | L10: Closed | M10: Closed | O10: ABJ/DIR/EKS/01.26/0046 | P10: ABJ/DIR/EKS/01.26/0046 | R10: Finance | S10: Nurul S | T10: =DATEDIF(C10,$Z$1,"Y")&" tahun, "&DATEDIF(C10,$Z$1,"YM")&" bulan, "&DATEDIF(C10,$Z$1,"MD")&" hari" -> 0 tahun, 9 bulan, 3 hari | U10: =DATEDIF(C10,Summary!$A$1,"d") -> 276 | W10: {=_xlfn.IFS(U10<=X10,X10,U10<=X10*2,X10*2,U10<=X10*3,X10*3,U10>X10*3,">"&X10*3)} -> Closed | X10: {=_xlfn.IFS(M10="Level 1",7,M10="Level 2",14,M10="Level 3","30",M10="Info","Info",M10="Closed","Closed")} -> Closed
A11: 10 | B11: 4719/PP.01.02/EKST/XII/2025 | C11: 46028 | D11: 46022 | E11: PAM JAYA | F11: Teguran terhadap Pengawasan Konsultan Pengawas Independen pada Dokumen Amandemen dan Pernyataan kembali Perjanjian Kerjasama Bundling | G11: Surat PAM JAYA kepada KPI SCI terkait teguran terhadap pengawasan pekerjaan, HSE, dan dokumentasi bahwa KPI belum optimal dalam peran sebagai Konsultan Pengawas Independen | H11: Project | I11: Project | J11: Kontrak & Legal | K11: Tidak | L11: Info | M11: Info | R11: Compliance | S11: Indradi | T11: =DATEDIF(C11,$Z$1,"Y")&" tahun, "&DATEDIF(C11,$Z$1,"YM")&" bulan, "&DATEDIF(C11,$Z$1,"MD")&" hari" -> 0 tahun, 9 bulan, 3 hari | U11: =DATEDIF(C11,Summary!$A$1,"d") -> 276 | W11: {=_xlfn.IFS(U11<=X11,X11,U11<=X11*2,X11*2,U11<=X11*3,X11*3,U11>X11*3,">"&X11*3)} -> Info | X11: {=_xlfn.IFS(M11="Level 1",7,M11="Level 2",14,M11="Level 3","30",M11="Info","Info",M11="Closed","Closed")} -> Info
A12: 11 | B12: e-70362/PM.01.00 | C12: 46028 | D12: 46007 | E12: PAM JAYA | F12: Permohonan Pemasangan Sambungan Langsung Air Minum Perpipaan di area Halim Perdana Kusuma | G12: Surat PAM JAYA kepada Komandan Pangkalan TNI AU perihal pemasangan SL di area Halim | H12: Project | I12: Greenfield | J12: Sambungan Langsung | K12: Tidak | L12: Info | M12: Info | R12: PMO NC | S12: A. Levi | T12: =DATEDIF(C12,$Z$1,"Y")&" tahun, "&DATEDIF(C12,$Z$1,"YM")&" bulan, "&DATEDIF(C12,$Z$1,"MD")&" hari" -> 0 tahun, 9 bulan, 3 hari | U12: =DATEDIF(C12,Summary!$A$1,"d") -> 276 | W12: {=_xlfn.IFS(U12<=X12,X12,U12<=X12*2,X12*2,U12<=X12*3,X12*3,U12>X12*3,">"&X12*3)} -> Info | X12: {=_xlfn.IFS(M12="Level 1",7,M12="Level 2",14,M12="Level 3","30",M12="Info","Info",M12="Closed","Closed")} -> Info
A13: 12 | B13: 012/S/DIR/BPM-ABJ/I/2026 | C13: 46029 | D13: 46028 | E13: BPM | F13: Penagihan Pekerjaan Sambungan Langsung | G13: Konfirmasi pihak ABJ terhadap pengendaan denda terhadap keterlambatan SL | H13: Project | I13: Greenfield | J13: Sambungan Langsung | K13: Ya | L13: Closed | M13: Closed | O13: ABJ/DIR/EKS/01.26/0032 | P13: ABJ/DIR/EKS/01.26/0032 | R13: PMO NC | S13: A. Levi | T13: =DATEDIF(C13,$Z$1,"Y")&" tahun, "&DATEDIF(C13,$Z$1,"YM")&" bulan, "&DATEDIF(C13,$Z$1,"MD")&" hari" -> 0 tahun, 9 bulan, 2 hari | U13: =DATEDIF(C13,Summary!$A$1,"d") -> 275 | V13: lewat 30d | W13: {=_xlfn.IFS(U13<=X13,X13,U13<=X13*2,X13*2,U13<=X13*3,X13*3,U13>X13*3,">"&X13*3)} -> Closed | X13: {=_xlfn.IFS(M13="Level 1",7,M13="Level 2",14,M13="Level 3","30",M13="Info","Info",M13="Closed","Closed")} -> Closed
A14: 13 | B14: 4722/PS.04.03/EKST/XII/2025 | C14: 46031 | D14: 46022 | E14: PAM JAYA | F14: Tanggapan Pengiriman Dokumen Desain Akhir Program Rehabilitasi Proyek Brownfield Tahun 2026 | G14: PAM JAYA meminta ABJ untuk klarifikasi atas desain akhir maksimal 30 hari kerja sejak dokumen ditanggapi PAM/KPI | H14: Project | I14: Cyclical | J14: Perencanaan Program Greenfield | K14: Ya | L14: Closed | M14: Closed | O14: ABJ/DIR/EKS/01.26/0076 | P14: ABJ/DIR/EKS/01.26/0076 | R14: PMO Cyclical | S14: Agus H | T14: =DATEDIF(C14,$Z$1,"Y")&" tahun, "&DATEDIF(C14,$Z$1,"YM")&" bulan, "&DATEDIF(C14,$Z$1,"MD")&" hari" -> 0 tahun, 9 bulan, 0 hari | U14: =DATEDIF(C14,Summary!$A$1,"d") -> 273 | W14: {=_xlfn.IFS(U14<=X14,X14,U14<=X14*2,X14*2,U14<=X14*3,X14*3,U14>X14*3,">"&X14*3)} -> Closed | X14: {=_xlfn.IFS(M14="Level 1",7,M14="Level 2",14,M14="Level 3","30",M14="Info","Info",M14="Closed","Closed")} -> Closed
A15: 14 | B15: e-69888/PP.01.05 | C15: 46031 | D15: 46008 | E15: PAM JAYA | F15: Teguran atas Pelaksanaan Pemenuhan Perizinan Proyek Bundling | G15: PAM JAYA meminta ABJ untuk menyelesaikan pemenuhan kewajiban perizinan keseluruhan project bundling dan menyampaikan progress perizinan setiap kamis pukul 15.00 | H15: Project | I15: Greenfield | J15: Konstruksi Program Greenfield | K15: Tidak | L15: Info | M15: Info | R15: PMO/Permit | S15: Danny L; Rais S | T15: =DATEDIF(C15,$Z$1,"Y")&" tahun, "&DATEDIF(C15,$Z$1,"YM")&" bulan, "&DATEDIF(C15,$Z$1,"MD")&" hari" -> 0 tahun, 9 bulan, 0 hari | U15: =DATEDIF(C15,Summary!$A$1,"d") -> 273 | W15: {=_xlfn.IFS(U15<=X15,X15,U15<=X15*2,X15*2,U15<=X15*3,X15*3,U15>X15*3,">"&X15*3)} -> Info | X15: {=_xlfn.IFS(M15="Level 1",7,M15="Level 2",14,M15="Level 3","30",M15="Info","Info",M15="Closed","Closed")} -> Info
A16: 15 | B16: e-70776/PP.01.04 | C16: 46031 | D16: 46007 | E16: PAM JAYA | F16: Sanksi Denda atas Kegagalan Kinerja Periode Bulan November 2025 | G16: Denda kegagalan kinerja tekanan IPA Pejompongan 1 (11 November 2025) senilai Rp1.030.742 | H16: Produksi | I16: PJP 1 | J16: Denda & Kegagalan | K16: Ya | L16: Closed | M16: Closed | O16: ABJ/DIR/EKS/01.26/0037 | P16: ABJ/DIR/EKS/01.26/0037 | R16: Compliance | S16: Indradi | T16: =DATEDIF(C16,$Z$1,"Y")&" tahun, "&DATEDIF(C16,$Z$1,"YM")&" bulan, "&DATEDIF(C16,$Z$1,"MD")&" hari" -> 0 tahun, 9 bulan, 0 hari | U16: =DATEDIF(C16,Summary!$A$1,"d") -> 273 | W16: {=_xlfn.IFS(U16<=X16,X16,U16<=X16*2,X16*2,U16<=X16*3,X16*3,U16>X16*3,">"&X16*3)} -> Closed | X16: {=_xlfn.IFS(M16="Level 1",7,M16="Level 2",14,M16="Level 3","30",M16="Info","Info",M16="Closed","Closed")} -> Closed
